Workbook

Sheet Sheet2
A1: Paragrafo | B1: Module | C1: Section | D1: Disclosure # | E1: Disclosure Title | F1: Datapoint/ guidance | G1: Disclosure | H1: Note | I1: Data Type | J1: Source | K1: 1 Material or document where this info is stored
A2: 21 | B2: Basic | C2: Set-up | D2: n.a. | E2: Overview of Basic Guidance | F2: =IF(VALUE(A2)>66,"guidance","datapoint") -> datapoint | G2: The undertaking shall report on its environmental, social and business conduct issues (together ‘sustainability issues’) using the B1 to B11 disclosures below. | I2: n.a.
A3: 22 | B3: Basic | C3: Set-up | D3: n.a. | E3: Overview of Basic Guidance | F3: =IF(VALUE(A3)>66,"guidance","datapoint") -> datapoint | G3: If the undertaking wants to provide more comprehensive information, it may also integrate the metrics required from B1 to B11 with disclosures, selecting them from the Comprehensive Module. | I3: n.a.
A4: 23 | B4: Basic | C4: Set-up | D4: n.a. | E4: Overview of Basic Guidance | F4: =IF(VALUE(A4)>66,"guidance","datapoint") -> datapoint | G4: Additional guidance on disclosures B1 to B11 is available in paragraphs 66 to 209. | I4: n.a.
A5: 66 | B5: Basic | C5: Set-up | D5: n.a. | E5: Overview of Basic Guidance | F5: =IF(VALUE(A5)>66,"guidance","datapoint") -> datapoint | G5: The guidance below is intended as part of an ecosystem that will include also the development of further support guides by EFRAG, further digital tools and implementation support (educational activities, stakeholders’ engagement) that aim to facilitate the understanding of some of the technical elements in the guidance. | I5: n.a.
A6: 67 | B6: Basic | C6: Set-up | D6: n.a. | E6: Overview of Basic Guidance | F6: =IF(VALUE(A6)>66,"guidance","datapoint") -> guidance | G6: This guidance supports undertakings that wish to apply the Basic Module.
A7: 24 | B7: Basic | C7: General Information | D7: B1 | E7: Basis for preparation | F7: =IF(VALUE(A7)>66,"guidance","datapoint") -> datapoint | G7: The undertaking shall disclose: | H7: see list | I7: narrative | K7: Interview management ESG
A8: 24 | B8: Basic | C8: General Information | D8: B1 | E8: Basis for preparation | F8: =IF(VALUE(A8)>66,"guidance","datapoint") -> datapoint | G8: (a) which of the following options it has selected: | I8: narrative | K8: Interview management ESG
A9: 24 | B9: Basic | C9: General Information | D9: B1 | E9: Basis for preparation | F9: =IF(VALUE(A9)>66,"guidance","datapoint") -> datapoint | G9: i. OPTION A: Basic Module (only); or | I9: text | K9: Interview management ESG
A10: 24 | B10: Basic | C10: General Information | D10: B1 | E10: Basis for preparation | F10: =IF(VALUE(A10)>66,"guidance","datapoint") -> datapoint | G10: ii. OPTION B: Basic Module and Comprehensive Module; | I10: text | K10: Interview management ESG
A11: 24 | B11: Basic | C11: General Information | D11: B1 | E11: Basis for preparation | F11: =IF(VALUE(A11)>66,"guidance","datapoint") -> datapoint | G11: (b) if the undertaking has omitted a disclosure as it is deemed classified or sensitive information (see paragraph 19), the undertaking shall indicate the disclosure that has omitted. | I11: text | K11: Interview management ESG
A12: 24 | B12: Basic | C12: General Information | D12: B1 | E12: Basis for preparation | F12: =IF(VALUE(A12)>66,"guidance","datapoint") -> datapoint | G12: (c) whether the sustainability report has been prepared on an individual basis (i.e. the report is limited to the undertaking’s information only) or on a consolidated basis (i.e. the report includes information about the undertaking and its subsidiaries); | I12: text | K12: Interview management ESG
A13: 24 | B13: Basic | C13: General Information | D13: B1 | E13: Basis for preparation | F13: =IF(VALUE(A13)>66,"guidance","datapoint") -> datapoint | G13: (d) in case of a consolidated sustainability report, the list of the subsidiaries, including their registered address4, covered in the report; and | I13: text | K13: Balance/economics
A14: 24 | B14: Basic | C14: General Information | D14: B1 | E14: Basis for preparation | F14: =IF(VALUE(A14)>66,"guidance","datapoint") -> datapoint | G14: (e) the following information: | I14: text | K14: Balance/economics
A15: 24 | B15: Basic | C15: General Information | D15: B1 | E15: Basis for preparation | F15: =IF(VALUE(A15)>66,"guidance","datapoint") -> datapoint | G15: i. the undertaking’s legal form; | I15: text | K15: Balance/economics
A16: 24 | B16: Basic | C16: General Information | D16: B1 | E16: Basis for preparation | F16: =IF(VALUE(A16)>66,"guidance","datapoint") -> datapoint | G16: ii. NACE sector classification code(s); | I16: text | K16: Balance/economics
A17: 24 | B17: Basic | C17: General Information | D17: B1 | E17: Basis for preparation | F17: =IF(VALUE(A17)>66,"guidance","datapoint") -> datapoint | G17: iii. size of the balance sheet (in Euro); | I17: Euro | K17: Balance/economics
A18: 24 | B18: Basic | C18: General Information | D18: B1 | E18: Basis for preparation | F18: =IF(VALUE(A18)>66,"guidance","datapoint") -> datapoint | G18: iv. turnover (in Euro); | I18: Euro | K18: Balance/economics
A19: 24 | B19: Basic | C19: General Information | D19: B1 | E19: Basis for preparation | F19: =IF(VALUE(A19)>66,"guidance","datapoint") -> datapoint | G19: v. number of employees in headcount or full-time equivalents; | I19: numeric | K19: HR reporting
A20: 24 | B20: Basic | C20: General Information | D20: B1 | E20: Basis for preparation | F20: =IF(VALUE(A20)>66,"guidance","datapoint") -> datapoint | G20: vi. country of primary operations and location of significant asset(s); and | I20: text | K20: Governance overview | L20: Company profile / Bilancio
A21: 24 | B21: Basic | C21: General Information | D21: B1 | E21: Basis for preparation | F21: =IF(VALUE(A21)>66,"guidance","datapoint") -> datapoint | G21: vii. geolocation of sites owned, leased or managed. | I21: text | K21: Governance overview | L21: Company profile / Bilancio
A22: 25 | B22: Basic | C22: General Information | D22: B1 | E22: Basis for preparation | F22: =IF(VALUE(A22)>66,"guidance","datapoint") -> datapoint | G22: If the undertaking has obtained any sustainability-related certification or label, it shall provide a brief description of those (including, where relevant, the issuers of the certification or label, date and rating score). | I22: narrative | K22: Environmental certifications
A23: 68 | B23: Basic | C23: General Information | D23: B1 | E23: Basis for preparation | F23: =IF(VALUE(A23)>66,"guidance","datapoint") -> guidance | G23: When reporting on the legal form of the undertaking according to national legislation under paragraph 24(e)(i), the undertaking can choose from one of the following undertaking structures:
A24: 68 | B24: Basic | C24: General Information | D24: B1 | E24: Basis for preparation | F24: =IF(VALUE(A24)>66,"guidance","datapoint") -> guidance | G24: (a) private limited liability undertaking
A25: 68 | B25: Basic | C25: General Information | D25: B1 | E25: Basis for preparation | F25: =IF(VALUE(A25)>66,"guidance","datapoint") -> guidance | G25: (b) sole proprietorship
A26: 68 | B26: Basic | C26: General Information | D26: B1 | E26: Basis for preparation | F26: =IF(VALUE(A26)>66,"guidance","datapoint") -> guidance | G26: (c) partnership
A27: 68 | B27: Basic | C27: General Information | D27: B1 | E27: Basis for preparation | F27: =IF(VALUE(A27)>66,"guidance","datapoint") -> guidance | G27: (d) cooperative
A28: 68 | B28: Basic | C28: General Information | D28: B1 | E28: Basis for preparation | F28: =IF(VALUE(A28)>66,"guidance","datapoint") -> guidance | G28: (e) other (please specify based on country specifications for legal forms)
A29: 69 | B29: Basic | C29: General Information | D29: B1 | E29: Basis for preparation | F29: =IF(VALUE(A29)>66,"guidance","datapoint") -> guidance | G29: When reporting on the NACE code(s) of the undertaking under paragraph 24(e)(ii), NACE codes (Nomenclature statistique des Activités économiques dans la Communauté Européenne) are classifications of economic activities used in the European Union. They provide a standardizedframework for classifying economic activities into sectors, enabling comparability and a common understanding among the various EU countries.
A30: 70 | B30: Basic | C30: General Information | D30: B1 | E30: Basis for preparation | F30: =IF(VALUE(A30)>66,"guidance","datapoint") -> guidance | G30: The NACE code consists of a number of digits ranging from 2 to 5 depending on the level of specificity with which the economic activity is identified. The list of NACE codes can be found in the following document: REGULATION (EC) No 1893/2006. | H30: see table
A31: 71 | B31: Basic | C31: General Information | D31: B1 | E31: Basis for preparation | F31: =IF(VALUE(A31)>66,"guidance","datapoint") -> guidance | G31: When reporting the number of employees under paragraph 24(e)(v), full-time equivalent (FTE) is the number of full-time positions in an undertaking.
A32: 71 | B32: Basic | C32: General Information | D32: B1 | E32: Basis for preparation | F32: =IF(VALUE(A32)>66,"guidance","datapoint") -> guidance | G32: It can be calculated by dividing an employee's scheduled hours (total effective hours worked in a week) by the employer's hours for a full-time workweek (total hours performed by full-time employees).
A33: 71 | B33: Basic | C33: General Information | D33: B1 | E33: Basis for preparation | F33: =IF(VALUE(A33)>66,"guidance","datapoint") -> guidance | G33: For example, an employee who works 25 hours every week for a company where the full-time week is 40 hours represents a 0,625 FTE (i.e. 25/ 40 hours).
A34: 72 | B34: Basic | C34: General Information | D34: B1 | E34: Basis for preparation | F34: =IF(VALUE(A34)>66,"guidance","datapoint") -> guidance | G34: Headcount is the total number of people employed by the undertaking at a given time.
A35: 73 | B35: Basic | C35: General Information | D35: B1 | E35: Basis for preparation | F35: =IF(VALUE(A35)>66,"guidance","datapoint") -> guidance | G35: When reporting on the country of primary operations and the location of significant assets under paragraphs 24(e)(vi) and (vii), the undertaking shall disclose this information for each of its sites using the table | H35: see table
A36: 74 | B36: Basic | C36: General Information | D36: B1 | E36: Basis for preparation | F36: =IF(VALUE(A36)>66,"guidance","datapoint") -> guidance | G36: The geolocation of an undertaking is expected to be a valuable datapoint for stakeholders for theassessment of risks and opportunities connected to the SME, particularly in relation to the sustainability issues of climate change adaptation, water, ecosystems and biodiversity.
A37: 75 | B37: Basic | C37: General Information | D37: B1 | E37: Basis for preparation | F37: =IF(VALUE(A37)>66,"guidance","datapoint") -> guidance | G37: The geolocation shall be provided in spatial points for single units or polygon points defining the boundaries of a larger, less unit-like site, such as a farm, mine or facility. The undertaking may also provide a cluster of points to allow for the easy identification of the concerned area. The spatial points shall be provided as coordinates, with five decimal places (e.g. 0° 00′ 0.036″).
A38: 76 | B38: Basic | C38: General Information | D38: B1 | E38: Basis for preparation | F38: =IF(VALUE(A38)>66,"guidance","datapoint") -> guidance | G38: When disclosing the geolocation of sites owned, leased, or managed, the undertaking shall include the coordinates of the sites in the table shown in paragraph 73. The undertaking may use web mapping tools (e.g. google maps, apple maps) to identify the coordinates of sites that it owns, leases or manages. The undertaking may also use any appropriate software tools or platforms to further establish the perimeter or area of larger sites.
A39: 77 | B39: Basic | C39: General Information | D39: B1 | E39: Basis for preparation | F39: =IF(VALUE(A39)>66,"guidance","datapoint") -> guidance | G39: In relation to paragraph 25, sustainability-related certification can include registered eco-labels from an EU, national or international labelling scheme, corresponding to the main activity of an SME. For instance, the EU Ecolabel covers specific products, such as textiles and footwear, coverings (e.g. wood floor coverings), cleaning and personal care products, electronic equipment, or furniture. The undertaking may consult the EU Ecolabel Product Groups and Product Catalogue for further information
A40: 26 | B40: Basic | C40: General Information | D40: B2 | E40: Practices, policies and future initiatives for transitioning towards a more sustainable economy | F40: =IF(VALUE(A40)>66,"guidance","datapoint") -> datapoint | G40: If the undertaking has put in place specific practices, policies or future initiatives for transitioning towards a more sustainable economy, it shall state so. The undertaking shall state whether it has: | H40: see list | I40: narrative | K40: Interview management ESG
...

Sheet Tables 
A5: 70 | B5: Basic | C5: General Information | D5: B1 | E5: Basis for preparation | F5: The NACE code consists of a number of digits ranging from 2 to 5 depending on the level of specificity with which the economic activity is identified. The list of NACE codes can be found in the following document: REGULATION (EC) No 1893/2006.
F6: Level 1 - Section: Sections are identified by an alphabetic letter, and they define 21 general economic areas such as agriculture, manufacturing industry or commerce. | H6: text
F7: Level 2 - Division: The division is identified by a two-digit numerical code and identifies a specific sector within the general economic area. There are a total of 88 divisions. | H7: numeric
F8: Level 3 - Group: The group is identified by a three-digit numerical code (also considering the division's two digits) and defines a specific area within the sector. There are about 270 groups. | H8: numeric
F9: Level 4 - Class: The class is identified by a four-digit numerical code (considering the digits of division and group) and defines a specific activity within the group. There are about 450 classes. | H9: numeric
A11: 73 | B11: Basic | C11: General Information | D11: B1 | E11: Basis for preparation | F11: When reporting on the country of primary operations and the location of significant assets under paragraphs 24(e)(vi) and (vii), the undertaking shall disclose this information for each of its sites using the table
F12: Sites | G12: Address | H12: Postal Code | I12: City | J12: Country | K12: Coordinates (geolocation)
F13: Registered Office (e.g.)
F14: Warehouse (e.g.)
F15: Industrial Plant (e.g.)
A17: 78 | B17: Basic | C17: General Information | D17: B2 | E17: Practices, policies and future initiatives for transitioning towards a more sustainable economy | F17: Undertakings may use the following template to report on B2 datapoints
F18: Sustainability Issue | G18: Do you have existing sustainability practices/policies/future initiatives that address this? [YES/NO] | H18: Are they publicly available? [YES/NO] | I18: Do the policies have any targets? [YES/NO]
F19: Climate Change
F20: Pollution
F21: Water and Marine Resources
F22: Biodiversity and Ecosystems
F23: Circular Economy
F24: Own Workforce
F25: Workers in the Value Chain
F26: Affected Communities
F27: Consumers and end-users
F28: Business conduct
A30: 29 | B30: Basic | C30: Envi Metrics | D30: B3 | E30: Energy and greenhouse gas emissions | F30: The undertaking shall disclose its total energy consumption in MWh, with a breakdown as per the table below, if it can obtain the necessary information to provide such a breakdown:
G31: Renewable | H31: Non-renewable | I31: Total
F32: Electricity (as reflected in utility billings)
F33: Fuels
F34: Total
A36: 82 | B36: Basic | C36: Envi Metrics | D36: B3 | E36: Energy and greenhouse gas emissions | F36: Climate related impacts are significantly driven by energy consumption. Therefore, it is relevant to disclose both the quantity as well as the type – e.g. fossil fuels such as coal, oil and gas versus renewable energy – and mix of energy consumed. Examples of energy disclosures are total energy consumption broken down by fossil fuels and electricity. Other breakdowns may be reported such as consumption of purchased or self-generated electricity from renewable sources. An example of the information requested in paragraph 29 follows.
G37: Renewale Energy Consuption (MWh) | H37: Non-renewable Energy Comsuption (MWh) | I37: Total 202(x) Energy consuption (MWh)
F38: Electricity (as reflected in utility billings) | G38: 300 | H38: 186 | I38: 486
F39: Fuels | G39: 3 | H39: 7 | I39: 10
F40: Total | G40: 303 | H40: 193 | I40: 496
A42: 91 | B42: Basic | C42: Envi Metrics | D42: B3 | E42: Energy and greenhouse gas emissions | F42: Scope 1 and 2 emissions may be reported in the following format.
G43: 202(x) GHG emissions (tCO2e)
F44: Scope 1 | G44: 45
F45: Scope 2 | G45: 6
F46: Total | G46: 51
A48: 100 | B48: Basic | C48: Envi Metrics | D48: B3 | E48: Energy and greenhouse gas emissions | F48: Evaluating GHG emissions can be done in several ways, including by the calculation approach, measurement, or a combination of measurement and calculations. One common approach is based on calculating with use of emission factors (EF) – which may incorporate the global warming potential (GWP) of the GHG. Direct measurement using sensors (flow and concentration) can also be applied. The table below summarises the most common methods.
F49: GHG evaluation method | G49: Details | H49: Necessary dara
F50: Measuring | G50: Multiplying the quantities of gas directly measured by their respective global warming potential. | H50: Direct quantity of gas emitted obtained from gas measurement (flow, concentration, volume) Global warming potential (GWP) of the gases
...

Sheet Support
A1: Yes | C1: COPIA QUI <- | E1: Lista source B General Information | G1: Lista source C General Information | I1: Lista source B Envi | K1: Lista source C Envi | M1: Lista source B Social | O1: Lista source C Social | Q1: Lista source B Governance | S1: Lista Source C Governance
A2: Yes, but integration needed | E2: Interview management ESG | G2: Governance overview | I2: Environmental monitoring data | K2: Interview management ESG | M2: HR REPORTING | O2: Interview HR dept | Q2: Interview Legal dept | S2: Balance/economics
A3: No, but planned | E3: Interview management ESG | G3: Governance overview | I3: HSE reporting | K3: GHG inventory | M3: HR REPORTING | O3: Interview HR dept | Q3: Business conduct Policies and Management Systems | S3: Balance/economics
A4: No | E4: Interview management ESG | G4: Interview Procurement dept | I4: HSE reporting | K4: GHG inventory | M4: HR REPORTING | O4: Interview HR dept | Q4: Interview Legal dept | S4: Balance/economics
E5: Interview management ESG | G5: Interview top management | I5: Environmental monitoring data | K5: HSE REPORTING | M5: HR REPORTING | O5: Interview HR dept | Q5: Interview Legal dept | S5: Balance/economics
E6: Interview management ESG | G6: Procurement Reporting | I6: HSE reporting | K6: Interview management ESG | M6: HR REPORTING | O6: Interview HR dept | Q6: Interview Legal dept | S6: Balance/economics
E7: Interview Legal dept OR HR dept OR Procurement dept | K7: Interview management ESG | M7: HR REPORTING | O7: Interview HR dept | Q7: CFO/Legal Reporting | S7: Interview management ESG
G8: Interview management ESG | I8: Environmental monitoring data | K8: Interview management ESG | M8: HR REPORTING | O8: Interview HR dept | Q8: Business conduct Policies and Management Systems | S8: Interview management ESG
E9: Interview Legal dept OR HR dept OR Procurement dept | G9: Interview top management | I9: Interview HR dept AND HSE dept | M9: Interview HR dept | O9: Interview HR dept | Q9: CFO/Legal Reporting | S9: Interview Quality/Purchases dept
E10: Interview management ESG | G10: Interview top management | I10: Interview Procurement dept | K10: Interview management ESG | O10: Interview HR OR Legal dept | Q10: Interview Legal dept | S10: Balance/economics
E11: Balance/economics | G11: Interview top management | I11: Interview HR dept AND HSE dept | K11: Interview management ESG | M11: HR REPORTING | Q11: CFO/Legal Reporting | S11: Balance/economics
E12: Balance/economics | G12: Procurement Reporting | I12: Environmental monitoring data | K12: HSE REPORTING | O12: Interview HR dept | S12: Balance/economics
E13: HR reporting | G13: Business conduct Policies and Management Systems | I13: Interview HSE dept | K13: Interview management ESG | M13: Interview HR dept | O13: HR POLICY | S13: Balance/economics
E14: Interview management ESG | G14: Interview Procurement dept | I14: Interview HSE dept | K14: Interview management ESG | M14: HR REPORTING | O14: HR POLICY | S14: Balance/economics
E15: Interview management ESG | I15: Interview HSE dept | K15: Interview management ESG | M15: Interview HR dept | O15: HR POLICY
E16: ISO 14001 | G16: Business conduct Policies and Management Systems | I16: Interview HSE dept | K16: Interview management ESG | O16: HR POLICY | S16: Interview top managemen
E17: Interview Legal dept OR HR dept OR Procurement dept | G17: Interview management ESG | I17: Interview HSE dept | K17: Interview management ESG | O17: HR POLICY | S17: Interview top managemen
E18: Interview Legal dept OR HR dept OR Procurement dept | I18: Interview Quality/Purchases dept | K18: Interview management ESG | M18: HSE REPORTING | O18: HR POLICY | S18: Interview top managemen
E19: Interview Legal dept OR HR dept OR Procurement dept | I19: Interview Quality/Purchases dept | K19: Interview management ESG | M19: HSE REPORTING | O19: HSE POLICY | S19: Interview top managemen
E20: Interview Legal dept OR HR dept OR Procurement dept | I20: Interview Quality/Purchases dept | K20: GHG inventory | M20: HSE REPORTING | O20: Interview HR dept | S20: Interview top managemen
E21: Interview Legal dept OR HR dept OR Procurement dept | I21: Interview Quality/Purchases dept | K21: GHG inventory | M21: HR REPORTING | O21: Interview HR dept | S21: Interview management ESG
E22: Interview Legal dept OR HR dept OR Procurement dept | I22: Interview Legal dept OR HR dept OR Procurement dept | K22: HSE REPORTING | M22: HR REPORTING | O22: Interview HR dept OR ESG dept | S22: Interview management ESG
E23: Interview management ESG | I23: HSE REPORTING | K23: Interview management ESG | M23: HSE REPORTING | S23: Interview management ESG
E24: Interview management ESG | I24: Interview management ESG | K24: Interview management ESG | O24: Interview HR dept OR Legal dept | S24: Interview management ESG
E25: HR reporting | I25: Interview management ESG | K25: Interview management ESG | O25: Interview HR dept OR Legal dept | S25: Interview management ESG
E26: HR reporting | I26: Interview management ESG | K26: Interview management ESG | M26: HR/HSE policies | O26: Interview HR dept OR Legal dept | S26: Interview management ESG
I27: Interview management ESG | K27: Interview management ESG | M27: HR/HSE policies | O27: Interview HR dept OR Legal dept | S27: Interview management ESG
E28: HR reporting | I28: Interview management ESG | K28: ISO 14001 | M28: HR/HSE policies | O28: Interview HR dept OR Legal dept | S28: Interview management ESG
E29: HR reporting | I29: Interview management ESG | K29: GHG inventory | M29: Interview HR dept AND HSE dept | O29: Interview HR dept OR Legal dept | S29: Balance/economics
E30: Interview management ESG | I30: Interview management ESG | M30: HSE REPORTING | O30: Interview HR dept OR Legal dept | S30: Balance/economics
E31: Interview Legal dept OR HR dept OR Procurement dept | I31: Interview management ESG | K31: Interview management ESG | O31: Interview HR dept OR Legal dept | S31: Balance/economics
E32: Interview Legal dept OR HR dept OR Procurement dept | I32: Interview management ESG | K32: Interview management ESG | O32: Interview HR dept OR Legal dept | S32: Balance/economics
E33: Interview Quality dept | I33: Interview management ESG | K33: Interview risk manager OR ESG | M33: Remuneration policy | O33: HR REPORTING | S33: Balance/economics
I34: Interview management ESG | K34: Interview ESG OR Risk manager | M34: HR REPORTING | O34: Interview Procurement dept
E35: Interview management ESG | I35: Interview management ESG | K35: Interview ESG OR HSE dept | M35: Interview HR dept | S35: HR REPORTING
E36: HR/HSE action plane | I36: Interview management ESG | K36: Interview management ESG | M36: HR REPORTING | O36: HR REPORTING | S36: HR REPORTING
E37: HR/HSE policies | I37: Interview management ESG | K37: Interview Risk manager OR ESG | M37: Remuneration policy | O37: Interview HR dept | S37: HR REPORTING
E38: Transition plane | I38: Interview management ESG | K38: Interview ESG OR Risk manager | M38: Remuneration policy | O38: Interview HR dept | S38: HR REPORTING
E39: Resilience analysis | I39: Interview management ESG | K39: Interview ESG | M39: HR REPORTING | O39: Interview HR dept | S39: HR REPORTING
E40: Interview management ESG | I40: Interview management ESG | K40: Interview Risk manager | M40: HR REPORTING | O40: Procurement Reporting
...

Sheet Checklist_General_Information
B2: MODULO B - (BASE) | H2: MODULO C - (COMPREHENSIVE)
B3: GENERAL INFORMATION | C3: Item available? | D3: Data point coverage | E3: Comments | H3: GENERAL INFORMATION | I3: Item available? | J3: Data point coverage | K3: Comments
B4: {=_xlfn.UNIQUE(_xlfn._xlws.FILTER(Sheet2!K7:K46, Sheet2!K7:K46<>""))} -> Interview management ESG | D4: =COUNTIF(Sheet2!$K$7:$K$46, B4) -> 7 | H4: {=_xlfn.UNIQUE(_xlfn._xlws.FILTER(Sheet2!K321:K328, Sheet2!K321:K328<>""))} -> Governance overview | J4: =COUNTIF(Sheet2!$K$321:$K$328, H4) -> 3
B5: Balance/economics | D5: =COUNTIF(Sheet2!$K$7:$K$46, B5) -> 6 | H5: Interview management ESG | J5: =COUNTIF(Sheet2!$K$321:$K$328, H5) -> 1
B6: HR reporting | D6: =COUNTIF(Sheet2!$K$7:$K$46, B6) -> 1 | H6: HSE Action plan /Policies / Transition plan | J6: =COUNTIF(Sheet2!$K$321:$K$328, H6) -> 1
B7: Governance overview | D7: =COUNTIF(Sheet2!$K$7:$K$46, B7) -> 2 | H7: Sustainability Governance | J7: =COUNTIF(Sheet2!$K$321:$K$328, H7) -> 1
B8: Environmental certifications | D8: =COUNTIF(Sheet2!$K$7:$K$46, B8) -> 1
B9: HSE action plan | D9: =COUNTIF(Sheet2!$K$7:$K$46, B9) -> 1
B10: HSE policies | D10: =COUNTIF(Sheet2!$K$7:$K$46, B10) -> 1
B11: Transition plan | D11: =COUNTIF(Sheet2!$K$7:$K$46, B11) -> 3

Sheet Checklist_Environment
B2: MODULO B - (BASE) | H2: MODULO C - (COMPREHENSIVE)
B3: ENVIRONMENTAL | C3: Item available? | D3: Data point coverage | E3: Comments | H3: ENVIRONMENTAL | I3: Item available? | J3: Data point coverage | K3: Comments
B4: {=_xlfn.UNIQUE(_xlfn._xlws.FILTER(Sheet2!$K$53:$K$256, Sheet2!$K$53:$K$256<>""))} -> Energy consumption | D4: =COUNTIF(Sheet2!$K$53:$K$256, B4) -> 1 | H4: {=_xlfn.UNIQUE(_xlfn._xlws.FILTER(Sheet2!$K$329:$K$365, Sheet2!$K$329:$K$365<>""))} -> GHG emissions - Scope 3 | J4: =COUNTIF(Sheet2!$K$329:$K$365, H4) -> 1
B5: GHG emissions - Scope 1 & 2 | D5: =COUNTIF(Sheet2!$K$53:$K$256, B5) -> 4 | H5: Transition plan | J5: =COUNTIF(Sheet2!$K$329:$K$365, H5) -> 10
B6: Environmental monitoring data | D6: =COUNTIF(Sheet2!$K$53:$K$256, B6) -> 5 | H6: Climate risk assessment | J6: =COUNTIF(Sheet2!$K$329:$K$365, H6) -> 5
B7: Biodiversity metrics | D7: =COUNTIF(Sheet2!$K$53:$K$256, B7) -> 5 | J7: =COUNTIF(Sheet2!$K$329:$K$365, H7) -> 0
B8: Interview management ESG | D8: =COUNTIF(Sheet2!$K$53:$K$256, B8) -> 2 | J8: =COUNTIF(Sheet2!$K$329:$K$365, H8) -> 0
B9: Material purchased | D9: =COUNTIF(Sheet2!$K$53:$K$256, B9) -> 1 | J9: =COUNTIF(Sheet2!$K$329:$K$365, H9) -> 0
D10: =COUNTIF(Sheet2!$K$53:$K$256, B10) -> 0 | J10: =COUNTIF(Sheet2!$K$329:$K$365, H10) -> 0
D11: =COUNTIF(Sheet2!$K$53:$K$256, B11) -> 0 | J11: =COUNTIF(Sheet2!$K$329:$K$365, H11) -> 0
D12: =COUNTIF(Sheet2!$K$53:$K$256, B12) -> 0 | J12: =COUNTIF(Sheet2!$K$329:$K$365, H12) -> 0
D13: =COUNTIF(Sheet2!$K$53:$K$256, B13) -> 0 | I13: =IFERROR(_xlfn.XLOOKUP(H13,#REF!,#REF!),"")
D14: =COUNTIF(Sheet2!$K$53:$K$256, B14) -> 0 | I14: =IFERROR(_xlfn.XLOOKUP(H14,#REF!,#REF!),"")
D15: =COUNTIF(Sheet2!$K$53:$K$256, B15) -> 0 | I15: =IFERROR(_xlfn.XLOOKUP(H15,#REF!,#REF!),"")
D16: =COUNTIF(Sheet2!$K$53:$K$256, B16) -> 0 | I16: =IFERROR(_xlfn.XLOOKUP(H16,#REF!,#REF!),"")
D17: =COUNTIF(Sheet2!$K$53:$K$256, B17) -> 0
D18: =COUNTIF(Sheet2!$K$53:$K$256, B18) -> 0
D19: =COUNTIF(Sheet2!$K$53:$K$256, B19) -> 0
D20: =COUNTIF(Sheet2!$K$53:$K$256, B20) -> 0
D21: =COUNTIF(Sheet2!$K$53:$K$256, B21) -> 0
D22: =COUNTIF(Sheet2!$K$53:$K$256, B22) -> 0
C23: =IFERROR(_xlfn.XLOOKUP(B23,#REF!,#REF!),"")
C24: =IFERROR(_xlfn.XLOOKUP(B24,#REF!,#REF!),"")
C25: =IFERROR(_xlfn.XLOOKUP(B25,#REF!,#REF!),"")
C26: =IFERROR(_xlfn.XLOOKUP(B26,#REF!,#REF!),"")
C27: =IFERROR(_xlfn.XLOOKUP(B27,#REF!,#REF!),"")
C28: =IFERROR(_xlfn.XLOOKUP(B28,#REF!,#REF!),"")
C29: =IFERROR(_xlfn.XLOOKUP(B29,#REF!,#REF!),"")
C30: =IFERROR(_xlfn.XLOOKUP(B30,#REF!,#REF!),"")
C31: =IFERROR(_xlfn.XLOOKUP(B31,#REF!,#REF!),"")
C32: =IFERROR(_xlfn.XLOOKUP(B32,#REF!,#REF!),"")
C33: =IFERROR(_xlfn.XLOOKUP(B33,#REF!,#REF!),"")
C34: =IFERROR(_xlfn.XLOOKUP(B34,#REF!,#REF!),"")
... C42: =IFERROR(_xlfn.XLOOKUP(B42,#REF!,#REF!),"")

Sheet Checklist_Governance
B2: MODULO B - (BASIC) | H2: MODULO C - (COMPREHENSIVE)
B3: GOVERNANCE | C3: Item available? | D3: Data point coverage | E3: Comments | H3: GOVERNANCE | I3: Item available? | J3: Data point coverage | K3: Comments
B4: {=_xlfn.UNIQUE(_xlfn._xlws.FILTER(Sheet2!$K$311:$K$315, Sheet2!$K$311:$K$315<>""))} -> Interview Legal dept | D4: =COUNTIF(Sheet2!$K$311:$K$315, B4) -> 1 | H4: {=_xlfn.UNIQUE(_xlfn._xlws.FILTER(Sheet2!$K$395:$K$412, Sheet2!$K$395:$K$412<>""))} -> Balance/economics | J4: =COUNTIF(Sheet2!$K$395:$K$412, H4) -> 6
H5: HR Reporting | J5: =COUNTIF(Sheet2!$K$395:$K$412, H5) -> 1
C6: =IFERROR(_xlfn.XLOOKUP(B6,#REF!,#REF!),"")

Sheet Checklist_Social
B2: MODULO B - (BASE) | H2: MODULO C - (COMPREHENSIVE)
B3: SOCIAL | C3: Item available? | D3: Data point coverage | E3: Comments | H3: SOCIAL | I3: Item available? | J3: Data point coverage | K3: Comments
B4: {=_xlfn.UNIQUE(_xlfn._xlws.FILTER(Sheet2!$K$257:$K$310, Sheet2!$K$257:$K$310<>""))} -> HR REPORTING | D4: =COUNTIF(Sheet2!$K$257:$K$310, B4) -> 7 | H4: {=_xlfn.UNIQUE(_xlfn._xlws.FILTER(Sheet2!$K$366:$K$394, Sheet2!$K$366:$K$394<>""))} -> HR REPORTING | J4: =COUNTIF(Sheet2!$K$366:$K$394, H4) -> 2
B5: HSE REPORTING | D5: =COUNTIF(Sheet2!$K$257:$K$310, B5) -> 3 | H5: Code of Conduct | J5: =COUNTIF(Sheet2!$K$366:$K$394, H5) -> 9
B6: Interview HR dept/ Contracts | D6: =COUNTIF(Sheet2!$K$257:$K$310, B6) -> 2 | H6: Whistleblowing | J6: =COUNTIF(Sheet2!$K$366:$K$394, H6) -> 1
H7: Interview HR dept OR Legal dept | J7: =COUNTIF(Sheet2!$K$366:$K$394, H7) -> 8
C10: =IFERROR(_xlfn.XLOOKUP(B10,#REF!,#REF!),"")
I11: =IFERROR(_xlfn.XLOOKUP(H11,#REF!,#REF!),"")
I12: =IFERROR(_xlfn.XLOOKUP(H12,#REF!,#REF!),"")
I13: =IFERROR(_xlfn.XLOOKUP(H13,#REF!,#REF!),"")
I14: =IFERROR(_xlfn.XLOOKUP(H14,#REF!,#REF!),"")

Sheet DASHBOARD
B2: MODULO | C2: Yes | D2: Yes, but integration needed | E2: No | F2: No but planned | G2: TOT | H2: %
B3: BASE - General Information | C3: =SUMIF(Checklist_General_Information!$C$4:$C$100,"Yes",Checklist_General_Information!$D$4:$D$100) -> 0 | D3: =SUMIF(Checklist_General_Information!$C$4:$C$100,"Yes, but integration needed",Checklist_General_Information!$D$4:$D$100) -> 0 | E3: =SUMIF(Checklist_General_Information!$C$4:$C$100,"No",Checklist_General_Information!$D$4:$D$100) -> 0 | F3: =SUMIF(Checklist_General_Information!$C$4:$C$100,"No, but planned",Checklist_General_Information!$D$4:$D$100) -> 0 | G3: =SUM(C3:F3) -> 0 | H3: =G3/$G$11 -> #DIV/0!
B4: COMPREHENSIVE - General Information | C4: =SUMIF(Checklist_General_Information!$I$4:$I$100,"Yes",Checklist_General_Information!$J$4:$J$100) -> 0 | D4: =SUMIF(Checklist_General_Information!$I$4:$I$100,"Yes, but integration needed",Checklist_General_Information!$J$4:$J$100) -> 0 | E4: =SUMIF(Checklist_General_Information!$I$4:$I$100,"No",Checklist_General_Information!$J$4:$J$100) -> 0 | F4: =SUMIF(Checklist_General_Information!$I$4:$I$100,"No, but planned",Checklist_General_Information!$J$4:$J$100) -> 0 | G4: =SUM(C4:F4) -> 0 | H4: =G4/$G$11 -> #DIV/0!
B5: BASE - Environment | C5: =SUMIF(Checklist_Environment!$C$4:$C$100,"Yes",Checklist_Environment!$D$4:$D$100) -> 0 | D5: =SUMIF(Checklist_Environment!$C$4:$C$100,"Yes, but integration needed",Checklist_Environment!$D$4:$D$100) -> 0 | E5: =SUMIF(Checklist_Environment!$C$4:$C$100,"No",Checklist_Environment!$D$4:$D$100) -> 0 | F5: =SUMIF(Checklist_Environment!$C$4:$C$100,"No, but planned",Checklist_Environment!$D$4:$D$100) -> 0 | G5: =SUM(C5:F5) -> 0 | H5: =G5/$G$11 -> #DIV/0!
B6: COMPREHENSIVE - Environment | C6: =SUMIF(Checklist_Environment!$I$4:$I$100,"Yes",Checklist_Environment!$J$4:$J$100) -> 0 | D6: =SUMIF(Checklist_Environment!$I$4:$I$100,"Yes, but integration needed",Checklist_Environment!$J$4:$J$100) -> 0 | E6: =SUMIF(Checklist_Environment!$I$4:$I$100,"No",Checklist_Environment!$J$4:$J$100) -> 0 | F6: =SUMIF(Checklist_Environment!$I$4:$I$100,"No, but planned",Checklist_Environment!$J$4:$J$100) -> 0 | G6: =SUM(C6:F6) -> 0 | H6: =G6/$G$11 -> #DIV/0!
B7: BASE - Social | C7: =SUMIF(Checklist_Social!$C$4:$C$100,"Yes",Checklist_Social!$D$4:$D$100) -> 0 | D7: =SUMIF(Checklist_Social!$C$4:$C$100,"Yes, but integration needed",Checklist_Social!$D$4:$D$100) -> 0 | E7: =SUMIF(Checklist_Social!$C$4:$C$100,"No",Checklist_Social!$D$4:$D$100) -> 0 | F7: =SUMIF(Checklist_Social!$C$4:$C$100,"No, but planned",Checklist_Social!$D$4:$D$100) -> 0 | G7: =SUM(C7:F7) -> 0 | H7: =G7/$G$11 -> #DIV/0!
B8: COMPREHENSIVE - Social | C8: =SUMIF(Checklist_Social!$I$4:$I$100,"Yes",Checklist_Social!$J$4:$J$100) -> 0 | D8: =SUMIF(Checklist_Social!$I$4:$I$100,"Yes, but integration needed",Checklist_Social!$J$4:$J$100) -> 0 | E8: =SUMIF(Checklist_Social!$I$4:$I$100,"No",Checklist_Social!$J$4:$J$100) -> 0 | F8: =SUMIF(Checklist_Social!$I$4:$I$100,"No, but planned",Checklist_Social!$J$4:$J$100) -> 0 | G8: =SUM(C8:F8) -> 0 | H8: =G8/$G$11 -> #DIV/0!
B9: BASE - Governance | C9: =SUMIF(Checklist_Governance!$C$4:$C$100,"Yes",Checklist_Governance!$D$4:$D$100) -> 0 | D9: =SUMIF(Checklist_Governance!$C$4:$C$100,"Yes, but integration needed",Checklist_Governance!$D$4:$D$100) -> 0 | E9: =SUMIF(Checklist_Governance!$C$4:$C$100,"No",Checklist_Governance!$D$4:$D$100) -> 0 | F9: =SUMIF(Checklist_Governance!$C$4:$C$100,"No, but planned",Checklist_Governance!$D$4:$D$100) -> 0 | G9: =SUM(C9:F9) -> 0 | H9: =G9/$G$11 -> #DIV/0!
B10: COMPREHENSIVE - Governace | C10: =SUMIF(Checklist_Governance!$I$4:$I$100,"Yes",Checklist_Governance!$J$4:$J$100) -> 0 | D10: =SUMIF(Checklist_Governance!$I$4:$I$100,"Yes, but integraion needed",Checklist_Governance!$J$4:$J$100) -> 0 | E10: =SUMIF(Checklist_Governance!$I$4:$I$100,"No",Checklist_Governance!$J$4:$J$100) -> 0 | F10: =SUMIF(Checklist_Governance!$I$4:$I$100,"No, but planned",Checklist_Governance!$J$4:$J$100) -> 0 | G10: =SUM(C10:F10) -> 0 | H10: =G10/$G$11 -> #DIV/0!
B11: TOT | C11: =SUM(C3:C10) -> 0 | D11: =SUM(D3:D10) -> 0 | E11: =SUM(E3:E10) -> 0 | F11: =SUM(F3:F10) -> 0 | G11: =SUM(G3:G10) -> 0 | H11: =G11/$G$11 -> #DIV/0!
B12: % | C12: =C11/$G$11 -> #DIV/0! | D12: =D11/$G$11 -> #DIV/0! | E12: =E11/$G$11 -> #DIV/0! | F12: =F11/$G$11 -> #DIV/0! | G12: =G11/$G$11 -> #DIV/0!
B15: MODULO BASIC | C15: Yes | D15: Yes, but integration needed | E15: No | F15: No but planned | G15: TOT | H15: %
B16: BASE - General Information | C16: =SUMIF(Checklist_General_Information!$C$4:$C$100,"Yes",Checklist_General_Information!$D$4:$D$100) -> 0 | D16: =SUMIF(Checklist_General_Information!$C$4:$C$100,"Yes, but integration needed",Checklist_General_Information!$D$4:$D$100) -> 0 | E16: =SUMIF(Checklist_General_Information!$C$4:$C$100,"No",Checklist_General_Information!$D$4:$D$100) -> 0 | F16: =SUMIF(Checklist_General_Information!$C$4:$C$100,"No, but planned",Checklist_General_Information!$D$4:$D$100) -> 0 | G16: =SUM(C16:F16) -> 0 | H16: =G16/$G$11 -> #DIV/0!
B17: BASE - Environment | C17: =SUMIF(Checklist_Environment!$C$4:$C$100,"Yes",Checklist_Environment!$D$4:$D$100) -> 0 | D17: =SUMIF(Checklist_Environment!$C$4:$C$100,"Yes, but integration needed",Checklist_Environment!$D$4:$D$100) -> 0 | E17: =SUMIF(Checklist_Environment!$C$4:$C$100,"No",Checklist_Environment!$D$4:$D$100) -> 0 | F17: =SUMIF(Checklist_Environment!$C$4:$C$100,"No, but planned",Checklist_Environment!$D$4:$D$100) -> 0 | G17: =SUM(C17:F17) -> 0 | H17: =G17/$G$11 -> #DIV/0!
B18: BASE - Social | C18: =SUMIF(Checklist_Social!$C$4:$C$100,"Yes",Checklist_Social!$D$4:$D$100) -> 0 | D18: =SUMIF(Checklist_Social!$C$4:$C$100,"Yes, but integration needed",Checklist_Social!$D$4:$D$100) -> 0 | E18: =SUMIF(Checklist_Social!$C$4:$C$100,"No",Checklist_Social!$D$4:$D$100) -> 0 | F18: =SUMIF(Checklist_Social!$C$4:$C$100,"No, but planned",Checklist_Social!$D$4:$D$100) -> 0 | G18: =SUM(C18:F18) -> 0 | H18: =G18/$G$11 -> #DIV/0!
B19: BASE - Governance | C19: =SUMIF(Checklist_Governance!$C$4:$C$100,"Yes",Checklist_Governance!$D$4:$D$100) -> 0 | D19: =SUMIF(Checklist_Governance!$C$4:$C$100,"Yes, but integration needed",Checklist_Governance!$D$4:$D$100) -> 0 | E19: =SUMIF(Checklist_Governance!$C$4:$C$100,"No",Checklist_Governance!$D$4:$D$100) -> 0 | F19: =SUMIF(Checklist_Governance!$C$4:$C$100,"No, but planned",Checklist_Governance!$D$4:$D$100) -> 0 | G19: =SUM(C19:F19) -> 0 | H19: =G19/$G$11 -> #DIV/0!
B20: TOTALE | C20: =SUM(C16:C19) -> 0 | D20: =SUM(D16:D19) -> 0 | E20: =SUM(E16:E19) -> 0 | F20: =SUM(F16:F19) -> 0 | G20: =SUM(G16:G19) -> 0
B21: % | C21: =C20/$G$20 -> #DIV/0! | D21: =D20/$G$20 -> #DIV/0! | E21: =E20/$G$20 -> #DIV/0! | F21: =F20/$G$20 -> #DIV/0! | G21: =G20/$G$20 -> #DIV/0!
B25: MODULO COMPREHENSIVE | C25: Yes | D25: Yes, but integration needed | E25: No | F25: No but planned | G25: TOT | H25: %
B26: COMPREHENSIVE - General Information | C26: =SUMIF(Checklist_General_Information!$I$4:$I$100,"Yes",Checklist_General_Information!$J$4:$J$100) -> 0 | D26: =SUMIF(Checklist_General_Information!$I$4:$I$100,"Yes, but integration needed",Checklist_General_Information!$J$4:$J$100) -> 0 | E26: =SUMIF(Checklist_General_Information!$I$4:$I$100,"No",Checklist_General_Information!$J$4:$J$100) -> 0 | F26: =SUMIF(Checklist_General_Information!$I$4:$I$100,"No, but planned",Checklist_General_Information!$J$4:$J$100) -> 0 | G26: =SUM(C26:F26) -> 0 | H26: =G26/$G$11 -> #DIV/0!
B27: COMPREHENSIVE - Environment | C27: =SUMIF(Checklist_Environment!$I$4:$I$100,"Yes",Checklist_Environment!$J$4:$J$100) -> 0 | D27: =SUMIF(Checklist_Environment!$I$4:$I$100,"Yes, but integration needed",Checklist_Environment!$J$4:$J$100) -> 0 | E27: =SUMIF(Checklist_Environment!$I$4:$I$100,"No",Checklist_Environment!$J$4:$J$100) -> 0 | F27: =SUMIF(Checklist_Environment!$I$4:$I$100,"No, but planned",Checklist_Environment!$J$4:$J$100) -> 0 | G27: =SUM(C27:F27) -> 0 | H27: =G27/$G$11 -> #DIV/0!
B28: COMPREHENSIVE - Social | C28: =SUMIF(Checklist_Social!$I$4:$I$100,"Yes",Checklist_Social!$J$4:$J$100) -> 0 | D28: =SUMIF(Checklist_Social!$I$4:$I$100,"Yes, but integration needed",Checklist_Social!$J$4:$J$100) -> 0 | E28: =SUMIF(Checklist_Social!$I$4:$I$100,"No",Checklist_Social!$J$4:$J$100) -> 0 | F28: =SUMIF(Checklist_Social!$I$4:$I$100,"No, but planned",Checklist_Social!$J$4:$J$100) -> 0 | G28: =SUM(C28:F28) -> 0 | H28: =G28/$G$11 -> #DIV/0!
B29: COMPREHENSIVE - Governace | C29: =SUMIF(Checklist_Governance!$I$4:$I$100,"Yes",Checklist_Governance!$J$4:$J$100) -> 0 | D29: =SUMIF(Checklist_Governance!$I$4:$I$100,"Yes, but integraion needed",Checklist_Governance!$J$4:$J$100) -> 0 | E29: =SUMIF(Checklist_Governance!$I$4:$I$100,"No",Checklist_Governance!$J$4:$J$100) -> 0 | F29: =SUMIF(Checklist_Governance!$I$4:$I$100,"No, but planned",Checklist_Governance!$J$4:$J$100) -> 0 | G29: =SUM(C29:F29) -> 0 | H29: =G29/$G$11 -> #DIV/0!
B30: TOTALE | C30: =SUM(C26:C29) -> 0 | D30: =SUM(D26:D29) -> 0 | E30: =SUM(E26:E29) -> 0 | F30: =SUM(F26:F29) -> 0 | G30: =SUM(G26:G29) -> 0
B31: % | C31: =C30/$G$30 -> #DIV/0! | D31: =D30/$G$30 -> #DIV/0! | E31: =E30/$G$30 -> #DIV/0! | F31: =F30/$G$30 -> #DIV/0! | G31: =G30/$G$30 -> #DIV/0!
B34: TEMA - General information | C34: Yes | D34: Yes, but integration needed | E34: No | F34: No but planned | G34: TOT
B35: BASE - General Information | C35: =SUMIF(Checklist_General_Information!$C$4:$C$100,"Yes",Checklist_General_Information!$D$4:$D$100) -> 0 | D35: =SUMIF(Checklist_General_Information!$C$4:$C$100,"Yes, but integration needed",Checklist_General_Information!$D$4:$D$100) -> 0 | E35: =SUMIF(Checklist_General_Information!$C$4:$C$100,"No",Checklist_General_Information!$D$4:$D$100) -> 0 | F35: =SUMIF(Checklist_General_Information!$C$4:$C$100,"No, but planned",Checklist_General_Information!$D$4:$D$100) -> 0 | G35: =SUM(C35:F35) -> 0 | H35: =G35/$G$37 -> #DIV/0!
B36: COMPREHENSIVE - General Information | C36: =SUMIF(Checklist_General_Information!$I$4:$I$100,"Yes",Checklist_General_Information!$J$4:$J$100) -> 0 | D36: =SUMIF(Checklist_General_Information!$I$4:$I$100,"Yes, but integration needed",Checklist_General_Information!$J$4:$J$100) -> 0 | E36: =SUMIF(Checklist_General_Information!$I$4:$I$100,"No",Checklist_General_Information!$J$4:$J$100) -> 0 | F36: =SUMIF(Checklist_General_Information!$I$4:$I$100,"No, but planned",Checklist_General_Information!$J$4:$J$100) -> 0 | G36: =SUM(C36:F36) -> 0 | H36: =G36/$G$37 -> #DIV/0!
B37: TOTALE | C37: =SUM(C35:C36) -> 0 | D37: =SUM(D35:D36) -> 0 | E37: =SUM(E35:E36) -> 0 | F37: =SUM(F35:F36) -> 0 | G37: =SUM(C37:F37) -> 0 | H37: =G37/$G$37 -> #DIV/0!
B39: TEMA - AMBIENTE | C39: Yes | D39: Yes, but integration needed | E39: No | F39: No but planned | G39: TOT | H39: %
B40: BASE - Environment | C40: =SUMIF(Checklist_Environment!$C$4:$C$100,"Yes",Checklist_Environment!$D$4:$D$100) -> 0 | D40: =SUMIF(Checklist_Environment!$C$4:$C$100,"Yes, but integration needed",Checklist_Environment!$D$4:$D$100) -> 0 | E40: =SUMIF(Checklist_Environment!$C$4:$C$100,"No",Checklist_Environment!$D$4:$D$100) -> 0 | F40: =SUMIF(Checklist_Environment!$C$4:$C$100,"No, but planned",Checklist_Environment!$D$4:$D$100) -> 0 | G40: =SUM(C40:F40) -> 0 | H40: =G40/$G$42 -> #DIV/0!
B41: COMPREHENSIVE - Environment | C41: =SUMIF(Checklist_Environment!$I$4:$I$100,"Yes",Checklist_Environment!$J$4:$J$100) -> 0 | D41: =SUMIF(Checklist_Environment!$I$4:$I$100,"Yes, but integration needed",Checklist_Environment!$J$4:$J$100) -> 0 | E41: =SUMIF(Checklist_Environment!$I$4:$I$100,"No",Checklist_Environment!$J$4:$J$100) -> 0 | F41: =SUMIF(Checklist_Environment!$I$4:$I$100,"No, but planned",Checklist_Environment!$J$4:$J$100) -> 0 | G41: =SUM(C41:F41) -> 0 | H41: =G41/$G$42 -> #DIV/0!
B42: TOTALE | C42: =SUM(C40:C41) -> 0 | D42: =SUM(D40:D41) -> 0 | E42: =SUM(E40:E41) -> 0 | F42: =SUM(F40:F41) -> 0 | G42: =SUM(G40:G41) -> 0 | H42: =G42/$G$42 -> #DIV/0!
B44: TEMA - SOCIALE | C44: Yes | D44: Yes, but integration needed | E44: No | F44: No but planned | G44: TOT | H44: %
B45: BASE - Social | C45: =SUMIF(Checklist_Social!$C$4:$C$100,"Yes",Checklist_Social!$D$4:$D$100) -> 0 | D45: =SUMIF(Checklist_Social!$C$4:$C$100,"Yes, but integration needed",Checklist_Social!$D$4:$D$100) -> 0 | E45: =SUMIF(Checklist_Social!$C$4:$C$100,"No",Checklist_Social!$D$4:$D$100) -> 0 | F45: =SUMIF(Checklist_Social!$C$4:$C$100,"No, but planned",Checklist_Social!$D$4:$D$100) -> 0 | G45: =SUM(C45:F45) -> 0 | H45: =G45/$G$47 -> #DIV/0!
B46: COMPREHENSIVE - Social | C46: =SUMIF(Checklist_Social!$I$4:$I$100,"Yes",Checklist_Social!$J$4:$J$100) -> 0 | D46: =SUMIF(Checklist_Social!$I$4:$I$100,"Yes, but integration needed",Checklist_Social!$J$4:$J$100) -> 0 | E46: =SUMIF(Checklist_Social!$I$4:$I$100,"No",Checklist_Social!$J$4:$J$100) -> 0 | F46: =SUMIF(Checklist_Social!$I$4:$I$100,"No, but planned",Checklist_Social!$J$4:$J$100) -> 0 | G46: =SUM(C46:F46) -> 0 | H46: =G46/$G$47 -> #DIV/0!
B47: TOTALE | C47: =SUM(C45:C46) -> 0 | D47: =SUM(D45:D46) -> 0 | E47: =SUM(E45:E46) -> 0 | F47: =SUM(F45:F46) -> 0 | G47: =SUM(G45:G46) -> 0 | H47: =G47/$G$47 -> #DIV/0!
B49: TEMA - GOVERNANCE | C49: Yes | D49: Yes, but integration needed | E49: No | F49: No but planned | G49: TOT | H49: %
B50: BASE - Governance | C50: =SUMIF(Checklist_Governance!$C$4:$C$100,"Yes",Checklist_Governance!$D$4:$D$100) -> 0 | D50: =SUMIF(Checklist_Governance!$C$4:$C$100,"Yes, but integration needed",Checklist_Governance!$D$4:$D$100) -> 0 | E50: =SUMIF(Checklist_Governance!$C$4:$C$100,"No",Checklist_Governance!$D$4:$D$100) -> 0 | F50: =SUMIF(Checklist_Governance!$C$4:$C$100,"No, but planned",Checklist_Governance!$D$4:$D$100) -> 0 | G50: =SUM(C50:F50) -> 0 | H50: =G50/$G$52 -> #DIV/0!
B51: COMPREHENSIVE - Governace | C51: =SUMIF(Checklist_Governance!$I$4:$I$100,"Yes",Checklist_Governance!$J$4:$J$100) -> 0 | D51: =SUMIF(Checklist_Governance!$I$4:$I$100,"Yes, but integraion needed",Checklist_Governance!$J$4:$J$100) -> 0 | E51: =SUMIF(Checklist_Governance!$I$4:$I$100,"No",Checklist_Governance!$J$4:$J$100) -> 0 | F51: =SUMIF(Checklist_Governance!$I$4:$I$100,"No, but planned",Checklist_Governance!$J$4:$J$100) -> 0 | G51: =SUM(C51:F51) -> 0 | H51: =G51/$G$52 -> #DIV/0!
...
