Workbook

Sheet Diligèa
A1: B1 - Basis for preparation
A2: A cura di Diligèa | C2: Note
A3: Opzione | B3: B - Basic Module and Comprehensive Module
A4: Informazioni omesse in quanto ritenute riservate o sensibili? | C4: Se sì, indicare quali
A5: Perimetro rendicontazione | B5: Consolidato | C5: Indicare aziende nel perimetro

Sheet B1
A1: B1 - Basis for preparation
A2: Ragione sociale
A3: Codice NACE/ATECO
A5: Sedi | B5: Sede #1 | C5: Sede #2 | D5: Sede #3 | E5: aggiungere eventuali altre sedi
A6: Indirizzo
A7: Codice postale
A8: Città
A9: Paese
A10: Coordinate (geolocalizzazione)
A12: Dimensione | B12: 2024 | C12: 2025
A13: Totale degli attivi
A14: Fatturato
A15: Numero di dipendenti
A18: Certificazioni o marchi relativi alla sostenibilità | B18: The undertaking may consult the EU Ecolabel Product Groups and Product Catalogue for further information.
A19: Breve descrizione | B19: Organismo di certificazione | C19: Data | D19: Punteggio

Sheet B2
A1: B2 - Pratiche, politiche e iniziative future per la transizione verso un'economia più sostenibile
B2: Esistono pratiche/ politiche di sostenibilità/ iniziative future che affrontano uno dei seguenti temi di sostenibilità? [SÌ/NO] | C2: Sono disponibili pubblicamente? [SÌ/NO] | D2: Le politiche hanno degli obiettivi? [SÌ/NO]
A3: Cambiamento climatico
A4: Inquinamento
A5: Acqua e risorse marine
A6: Biodiversità ed ecosistemi
A7: Economia circolare
A8: Forza lavoro propria
A9: Lavoratori nella catena del valore
A10: Comunità interessate
A11: Consumatori e utenti finali
A12: Condotta aziendale

Sheet B2-C2
A1: B2 - Pratiche, politiche e iniziative future per la transizione verso un'economia più sostenibile
B2: Esistono pratiche/ politiche di sostenibilità/ iniziative future che affrontano uno dei seguenti temi di sostenibilità? [SÌ/NO] | C2: Sono disponibili pubblicamente? [SÌ/NO] | D2: Le politiche hanno degli obiettivi? [SÌ/NO]
A3: Cambiamento climatico
A4: Inquinamento
A5: Acqua e risorse marine
A6: Biodiversità ed ecosistemi
A7: Economia circolare
A8: Forza lavoro propria
A9: Lavoratori nella catena del valore
A10: Comunità interessate
A11: Consumatori e utenti finali
A12: Condotta aziendale
A14: C2 - Descrizione delle pratiche, politiche e iniziative future per la transizione verso un'economia più sostenibile
B15: Se avete risposto SÌ alle pratiche/alle politiche esistenti/alle iniziative future di cui all'informativa B2, descrivetele brevemente insieme alle azioni che ne conseguono. (Nel caso in cui la pratica/politica/iniziativa futura riguardi fornitori o clienti, l'impresa dovrà farne menzione) | C15: Se avete risposto SÌ alle iniziative/obiettivi futuri di cui all'informativa B2, specificateli. | D15: Indicare il livello dirigenziale più alto nell'impresa responsabile della loro attuazione [se presente].
A16: Cambiamento climatico
A17: Inquinamento
A18: Acqua e risorse marine
A19: Biodiversità ed ecosistemi
A20: Economia circolare
A21: Forza lavoro propria
A22: Lavoratori nella catena del valore
A23: Comunità interessate
A24: Consumatori e utenti finali
A25: Condotta aziendale

Sheet C1
A1: C1 – Strategia: modello di business e iniziative relative alla sostenibilità
A2: Descrizione dei principali gruppi di prodotti e/o servizi offerti
A3: Descrizione dei principali mercati in cui opera l'impresa (ad esempio B2B, vendita all'ingrosso, vendita al dettaglio, paesi)
A4: Descrizione delle principali relazioni commerciali (ad esempio fornitori chiave, clienti, canali di distribuzione e consumatori)
A5: La strategia presenta elementi chiave che riguardano o influenzano questioni di sostenibilità?
A6: Se sì, fornire una breve descrizione di tali elementi chiave

Sheet CarbonFootprint
A1: GHG category | B1: Item | C1: Quantità TOT 2024 | D1: UdM dato | E1: Benacchio 2024 | F1: nome file | G1: Stat 2024 | H1: nome file | I1: Benacchio 2025 | J1: Stat 2025 | K1: Note
A2: 1.1 - Stationary combustion sources | B2: Gas naturale | C2: 371686 | D2: Sm3 | E2: 182395 | F2: Estratto monitoraggio consumi | G2: 189291 | H2: Monitoraggi 2024 | I2: 152490 | J2: 106949 | K2: I valori qui inseriti vanno automaticamente a riempire il foglio B3
A3: 1.1 - Stationary combustion sources | B3: Fotovoltaico | C3: 856373.65 | D3: kWh | E3: 856373.65 | F3: Estratto Energia autoprodotta | I3: 1150012 | J3: 0 | K3: I valori qui inseriti vanno automaticamente a riempire il foglio B3
A4: 1.3 - Mobile combustion | B4: Auto di proprietà - Diesel | C4: 18575.21 | D4: liters | E4: 11811.97 | F4: Carburante x Achille (non assegnati + proprietà) | G4: 6763.24 | H4: Totale carburante | I4: 12800.53 | J4: 2904 | K4: I valori qui inseriti vanno automaticamente a riempire il foglio B3
A5: 1.3 - Mobile combustion | B5: Auto di proprietà / in leasing - benzina | C5: 4848.71 | D5: liters | G5: 4848.71 | H5: Totale carburante | K5: I valori qui inseriti vanno automaticamente a riempire il foglio B3
A6: 2.1 - Electricity consumption | B6: Elettricità acquistata (senza GDO) | C6: 4873436.6 | D6: kWh | E6: 3204360.6 | F6: Estratto monitoraggio consumi | G6: 1669076 | H6: Monitoraggi 2024 | I6: 3063397 | J6: 1843812 | K6: I valori qui inseriti vanno automaticamente a riempire il foglio B3
A7: 3.1 - ACQUISTI | B7: Acqua | C7: 1880 | D7: m3 | E7: 1880 | F7: Estratto monitoraggio consumi | I7: 1970 | J7: 533 | K7: I valori qui inseriti vanno automaticamente a riempire il foglio B7_M
A8: 3.1 - ACQUISTI | B8: Olio lubrificante | C8: 50197.3 | D8: kg | E8: 31524 | F8: Copia di impatto trasporti con tipo MP | G8: 18673.3 | H8: OLIO-GAS-FILI 2024 | I8: 25983.6 | J8: 15436 | K8: I valori qui inseriti vanno automaticamente a riempire il foglio B7_M
A9: 3.1 - ACQUISTI | B9: Acciaio inox | C9: 180444 | D9: kg | E9: 95221 | F9: Copia di impatto trasporti con tipo MP | G9: 85223 | H9: MP 2024 - con spostamenti | I9: 130000 | J9: 126068 | K9: I valori qui inseriti vanno automaticamente a riempire il foglio B7_M
A10: 3.1 - ACQUISTI | B10: Acciaio | C10: 24821539 | D10: kg | E10: 15752937 | F10: Copia di impatto trasporti con tipo MP | G10: 9068602 | H10: MP 2024 - con spostamenti | I10: 22037539 | J10: 7085186 | K10: I valori qui inseriti vanno automaticamente a riempire il foglio B7_M
A11: 3.1 - ACQUISTI | B11: Alluminio | C11: 389208 | D11: kg | E11: 370234 | F11: Copia di impatto trasporti con tipo MP | G11: 18974 | H11: MP 2024 - con spostamenti | I11: 426529.26 | J11: 9165 | K11: I valori qui inseriti vanno automaticamente a riempire il foglio B7_M
A12: 3.1 - ACQUISTI | B12: Azoto | C12: 46788 | D12: m3 | E12: 46788 | F12: Copia di impatto trasporti con tipo MP | I12: 28666 | J12: 0 | K12: I valori qui inseriti vanno automaticamente a riempire il foglio B7_M
A13: 3.1 - ACQUISTI | B13: CO2 | C13: 23840 | D13: m3 | E13: 23840 | F13: Copia di impatto trasporti con tipo MP | I13: 42135 | J13: 0 | K13: I valori qui inseriti vanno automaticamente a riempire il foglio B7_M
A14: 3.1 - ACQUISTI | B14: CO2 kg | C14: 8017 | D14: kg | G14: 8017 | H14: OLIO-GAS-FILI 2024 | J14: 2970 | K14: I valori qui inseriti vanno automaticamente a riempire il foglio B7_M
A15: 3.1 - ACQUISTI | B15: Argon liquido kg | C15: 81973.46 | D15: kg | E15: 55486.46 | F15: Consumo argon | G15: 26487 | H15: OLIO-GAS-FILI 2024 | I15: 46275 | J15: 13163 | K15: I valori qui inseriti vanno automaticamente a riempire il foglio B7_M
A16: 3.1 - ACQUISTI | B16: Ossigeno | C16: 5343 | D16: m3 | E16: 2461 | F16: Copia di impatto trasporti con tipo MP | G16: 2882 | H16: OLIO-GAS-FILI 2024 | I16: 180 | J16: 43.6 | K16: I valori qui inseriti vanno automaticamente a riempire il foglio B7_M
A17: 3.1 - ACQUISTI | B17: Gas saldatura m3 | C17: 2812 | D17: m3 | E17: 2765 | F17: Copia di impatto trasporti con tipo MP | G17: 47 | H17: OLIO-GAS-FILI 2024 | I17: 1800 | J17: 8.75 | K17: I valori qui inseriti vanno automaticamente a riempire il foglio B7_M
A18: 3.1 - ACQUISTI | B18: Gas saldatura kg | C18: 1899 | D18: kg | F18: Copia di impatto trasporti con tipo MP | G18: 1899 | H18: OLIO-GAS-FILI 2024 | K18: I valori qui inseriti vanno automaticamente a riempire il foglio B7_M
A19: 3.1 - ACQUISTI | B19: Filo saldatura | C19: 117250 | D19: kg | E19: 105000 | F19: Copia di impatto trasporti con tipo MP | G19: 12250 | H19: OLIO-GAS-FILI 2024 | I19: 69350 | J19: 11950 | K19: I valori qui inseriti vanno automaticamente a riempire il foglio B7_M
A20: 3.1 - ACQUISTI | B20: Verniciatura | C20: 271421.51 | D20: m2 | E20: 271421.51 | F20: Verniciatura 2024 v2 | K20: I valori qui inseriti vanno automaticamente a riempire il foglio B7_M
A21: 3.1 - ACQUISTI | B21: Verniciatura per kg | C21: 25100 | D21: kg | G21: 25100 | H21: email | J21: 24900 | K21: I valori qui inseriti vanno automaticamente a riempire il foglio B7_M
A22: 3.5 - RIFIUTI | B22: apparecchiature fuori uso 160214, diverse da quelle di cui alle voci da 160209 a 160213 | C22: 856 | D22: kg | E22: 231 | F22: Estratto rifiuti e formulario 2024 | G22: 625 | H22: Analisi quantitativi rifiuti | I22: 0 | J22: 8973 | K22: I valori qui inseriti vanno automaticamente a riempire il foglio B7_R
A23: 3.5 - RIFIUTI | B23: ferro e acciaio 170405 | C23: 139300 | D23: kg | E23: 100 | F23: Estratto rifiuti e formulario 2024 | G23: 139200 | H23: Analisi quantitativi rifiuti | I23: 0 | J23: 114730 | K23: I valori qui inseriti vanno automaticamente a riempire il foglio B7_R
A24: 3.5 - RIFIUTI | B24: imballaggi in legno 150103 | C24: 39140 | D24: kg | E24: 39140 | F24: Estratto rifiuti e formulario 2024 | G24: 0 | H24: Analisi quantitativi rifiuti | I24: 50530 | J24: 13330 | K24: I valori qui inseriti vanno automaticamente a riempire il foglio B7_R
A25: 3.5 - RIFIUTI | B25: imballaggi in materiali misti 150106 | C25: 131830 | D25: kg | E25: 49740 | F25: Estratto rifiuti e formulario 2024 | G25: 82090 | H25: Analisi quantitativi rifiuti | I25: 49650 | J25: 69200 | K25: I valori qui inseriti vanno automaticamente a riempire il foglio B7_R
A26: 3.5 - RIFIUTI | B26: limatura e trucioli di materiali ferrosi 120101 | C26: 49370 | D26: kg | E26: 49370 | F26: Estratto rifiuti e formulario 2024 | I26: 52730 | J26: 0 | K26: I valori qui inseriti vanno automaticamente a riempire il foglio B7_R
A27: 3.5 - RIFIUTI | B27: polveri e particolato di materiali ferrosi 120102 | C27: 8459287 | D27: kg | E27: 5733217 | F27: Estratto rifiuti e formulario 2024 | G27: 2726070 | H27: Analisi quantitativi rifiuti | I27: 5398816 | J27: 3249984 | K27: I valori qui inseriti vanno automaticamente a riempire il foglio B7_R
A28: 3.5 - RIFIUTI | B28: polveri e particolato di materiali non ferrosi 120104 | C28: 177630 | D28: kg | E28: 134870 | F28: Estratto rifiuti e formulario 2024 | G28: 42760 | H28: Analisi quantitativi rifiuti | I28: 90260 | J28: 35120 | K28: I valori qui inseriti vanno automaticamente a riempire il foglio B7_R
A29: 3.5 - RIFIUTI | B29: rifiuti liquidi acquosi 161002, diversi da quelli di cui alla voce 16 10 01 | C29: 26950 | D29: kg | E29: 26950 | F29: Estratto rifiuti e formulario 2024 | I29: 31150 | J29: 9160 | K29: I valori qui inseriti vanno automaticamente a riempire il foglio B7_R
A30: 3.5 - RIFIUTI | B30: toner per stampa esauriti 080318, diversi da quelli di cui alla voce 080317 | C30: 19 | D30: kg | E30: 19 | F30: Estratto rifiuti e formulario 2024 | I30: 0 | J30: 0 | K30: I valori qui inseriti vanno automaticamente a riempire il foglio B7_R
A31: 3.5 - RIFIUTI | B31: oli minerali per circuiti idraulici, non clorurati 130110 | C31: 3260 | D31: kg | E31: 3260 | F31: Estratto rifiuti e formulario 2024 | I31: 970 | J31: 0 | K31: I valori qui inseriti vanno automaticamente a riempire il foglio B7_R
A32: 3.5 - RIFIUTI | B32: oli minerali per motori, ingranaggi e lubrificazione, non clorurati 130205 | C32: 4940 | D32: kg | E32: 4940 | F32: Estratto rifiuti e formulario 2024 | I32: 7740 | J32: 4000 | K32: I valori qui inseriti vanno automaticamente a riempire il foglio B7_R
A33: 3.5 - RIFIUTI | B33: oli e altre emulsioni 130802 | C33: 13630 | D33: kg | E33: 13630 | F33: Estratto rifiuti e formulario 2024 | I33: 7350 | J33: 0 | K33: I valori qui inseriti vanno automaticamente a riempire il foglio B7_R
A34: 3.5 - RIFIUTI | B34: assorbenti, materiali filtranti (inclusi filtri dell'olio non specificati altrimenti), stracci e indumenti protettivi, contaminati da sostanze pericolose 150202 | C34: 2815 | D34: kg | E34: 2815 | F34: Estratto rifiuti e formulario 2024 | H34: Analisi quantitativi rifiuti | I34: 240 | J34: 1520 | K34: I valori qui inseriti vanno automaticamente a riempire il foglio B7_R
A35: 3.5 - RIFIUTI | B35: apparecchiature fuori uso, contenenti componenti pericolosi (3) 160213, diversi da quelli di cui alle voci da 160209 a 160212 | C35: 34 | D35: kg | E35: 34 | F35: Estratto rifiuti e formulario 2024 | I35: 0 | J35: 0 | K35: I valori qui inseriti vanno automaticamente a riempire il foglio B7_R
A36: 3.5 - RIFIUTI | B36: 150110 - imballaggi contenenti residui di sostanze pericolose o contaminati da tali sostanze | C36: 2330 | D36: kg | G36: 2330 | H36: Analisi quantitativi rifiuti | I36: 0 | J36: 100 | K36: I valori qui inseriti vanno automaticamente a riempire il foglio B7_R
A37: 3.5 - RIFIUTI | B37: 200121 - Tubi fluorescenti ed altri rifiuti contenenti mercurio | C37: 815 | D37: kg | G37: 815 | H37: Analisi quantitativi rifiuti | I37: 0 | J37: 15 | K37: I valori qui inseriti vanno automaticamente a riempire il foglio B7_R
A38: 3.7 - Commuting | B38: Trasporto casa/lavoro dipendenti - automobile | C38: 1912910 | D38: km | E38: 851000 | F38: Distanza casa lavoro dip_Benacchio | G38: 1061910 | H38: Tragitto casa lavoro
A39: 3.7 - Commuting | B39: Trasporto casa/lavoro dipendenti - bus | C39: 55890 | D39: pkm | G39: 55890 | H39: Tragitto casa lavoro
A40: 3.4 - Transport in | B40: Transport INGRESSO materie prime primarie- camion | C40: 4274230.7 | D40: tkm | E40: 2926471.6 | F40: Copia di impatto trasporti con tipo MP | G40: 1347759.1 | H40: MP 2024 - con spostamenti
...

Sheet B3-C3-C4
A1: B3 - Energia e emissioni di gas a effetto serra
A2: B3 - Energia e emissioni di gas a effetto serra | B2: UdM | C2: Sede 1 - 2024 | D2: Sede 2 - 2024 | E2: Sede 1 - 2025 | F2: Sede 2 - 2025
A3: Energia elettrica acquistata senza GdO
A4: Energia elettrica acquistata con GdO
A5: Energia elettrica autoprodotta da fonti rinnovabili
A6: Benzina per autotrazione
A7: Gasolio per autotrazione
A8: GPL per autotrazione
A9: Metano per autotrazione
A10: Metano per alimentazione caldaie/macchinari
A11: GPL per alimentazione caldaie/macchinari
A12: Gasolio per alimentazione caldaie/macchinari
A13: *Aggiungere righe nella tabella se necessario
A14: Totale Energia rinnovabile | C14: =C4+C5 -> 0 | D14: =D4+D5 -> 0 | F14: =F4+F5 -> 0
A15: Totale Energia non rinnovabile
A16: Totale rinnovabile e non rinnovabile
A18: A cura di Diligèa
A19: Emissioni GHG Scope 1 | B19: ton CO2eq
A20: Emissioni GHG Scope 2 (location-based) | B20: ton CO2eq
A21: Emissioni GHG Scope 3 (location-based) | B21: ton CO2eq
A22: GHG intensity | B22: ton CO2eq/€ | D22: =(D19+D20)/'B1'!B14 -> #DIV/0! | F22: =(F19+F20)/'B1'!C14 -> #DIV/0!
A26: B3 - Energia e emissioni di gas a effetto serra | B26: UdM | C26: Sede 1 - 2024 | D26: Sede 2 - 2024 | E26: Totale 2024 | F26: Sede 1 - 2025 | G26: Sede 2 - 2025 | H26: Totale 2025 | I26: Delta % 2025-2024
A27: Elettricità acquistata | B27: =B3 -> 0 | C27: =C3 -> 0 | D27: =D3 -> 0 | E27: =SUM(D27+C27) -> 0 | F27: =E3 -> 0 | G27: =F3 -> 0 | H27: =SUM(G27+F27) -> 0 | I27: =H27/E27-1 -> #DIV/0!
A28: Elettricità autoprodotta da fonti rinnovabili | B28: =B5 -> 0 | C28: =C5 -> 0 | D28: =D5 -> 0 | E28: =SUM(D28+C28) -> 0 | F28: =E5 -> 0 | G28: =F5 -> 0 | H28: =SUM(G28+F28) -> 0 | I28: =H28/E28-1 -> #DIV/0!
A29: Gas Naturale | B29: =B10 -> 0 | C29: =C10 -> 0 | D29: =D10 -> 0 | E29: =SUM(D29+C29) -> 0 | F29: =E10 -> 0 | G29: =F10 -> 0 | H29: =SUM(G29+F29) -> 0 | I29: =H29/E29-1 -> #DIV/0!
A30: Gasolio | B30: =B7 -> 0 | C30: =C7 -> 0 | D30: =D7 -> 0 | E30: =SUM(D30+C30) -> 0 | F30: =E7 -> 0 | G30: =F7 -> 0 | H30: =SUM(G30+F30) -> 0 | I30: =H30/E30-1 -> #DIV/0!
A31: Benzina | B31: =B6 -> 0 | C31: =C6 -> 0 | D31: =D6 -> 0 | E31: =SUM(D31+C31) -> 0 | F31: =E6 -> 0 | G31: =F6 -> 0 | H31: =SUM(G31+F31) -> 0 | I31: =H31/E31-1 -> #DIV/0!

Sheet B3
A1: B3 - Energia e emissioni di gas a effetto serra
A2: B3 - Energia e emissioni di gas a effetto serra | B2: UdM | C2: 2023 | D2: 2024
A3: Energia elettrica acquistata senza GdO
A4: Energia elettrica acquistata con GdO
A5: Energia elettrica autoprodotta da fonti rinnovabili
A6: Benzina per autotrazione
A7: Gasolio per autotrazione
A8: GPL per autotrazione
A9: Metano per autotrazione
A10: Metano per alimentazione caldaie/macchinari
A11: GPL per alimentazione caldaie/macchinari
A12: Gasolio per alimentazione caldaie/macchinari
A13: *Aggiungere righe nella tabella se necessario
A17: A cura di Diligèa
A18: Emissioni GHG Scope 1 | B18: ton CO2eq
A19: Emissioni GHG Scope 2 (location-based) | B19: ton CO2eq
A20: Emissioni GHG Scope 3 (location-based) | B20: ton CO2eq
A21: GHG intensity | B21: ton CO2eq/€ | C21: =(C18+C19)/'B1'!B14 -> #DIV/0! | D21: =(D18+D19)/'B1'!C14 -> #DIV/0!

Sheet B4
A1: Nota - compilare la tabella indicando le quantità corrispondenti a ciascuna sostanza inquinante che l'Organizzazione emette nell'aria, nell'acqua e nel suolo durante le proprie attività se: 1. l'Organizzazione è già tenuta per legge a comunicarle alle autorità competenti 2. l'Organizzazione le comunica volontariamente in base a un sistema di gestione ambientale
A3: B4 - Inquinamento di acqua, aria e suolo
A4: Inquinante | B4: Rilasciato in | C4: Emissioni [kg] 2024 | D4: Emissioni [kg] 2025
B5: Acqua
B6: Aria
B7: Suolo
A8: *Aggiungere linee se servono

Sheet B5
A1: B5 - Biodiversità
A2: B5 - Biodiversità | B2: Sede #1 (dati da B1) | C2: Sede #2 (dati da B1) | D2: Sede #3 (dati da B1) | F2: To identify protected areas and biodiversity sensitive areas, the undertaking may refer to databases such as the World Database on Protected Areas (WDPA) (a global database to help identify marine and terrestrial protected areas), the World Database on Key Biodiversity Areas, and the IUCN Red List of Threatened Species. The undertaking may also use tools such as the Integrated Biodiversity Assessment Tool (IBAT). https://natura2000.eea.europa.eu/ https://www.keybiodiversityareas.org/sites/search https://whc.unesco.org/en/list/
A3: Indirizzo | B3: ='B1'!B6 -> 0 | C3: ='B1'!C6 -> 0 | D3: ='B1'!D6 -> 0
A4: Codice postale | B4: ='B1'!B7 -> 0 | C4: ='B1'!C7 -> 0 | D4: ='B1'!D7 -> 0
A5: Città | B5: ='B1'!B8 -> 0 | C5: ='B1'!C8 -> 0 | D5: ='B1'!D8 -> 0
A6: Paese | B6: ='B1'!B9 -> 0 | C6: ='B1'!C9 -> 0 | D6: ='B1'!D9 -> 0
A7: Coordinate (geolocalizzazione) | B7: ='B1'!B10 -> 0 | C7: ='B1'!C10 -> 0 | D7: ='B1'!D10 -> 0
A8: Area (ha)*
A9: Area protetta (biodiversity sensitive area)*
A10: Note
A11: *A cura di Diligèa
A13: Sede #1 | B13: 2024 | C13: 2025 | D13: % change | F13: Note: Per “area impermeabilizzata” si intende un'area in cui il suolo originario è stato ricoperto (ad esempio strade, edifici, parcheggi), rendendolo impermeabile e determinando un impatto sull'ambiente. L'area verde o “area orientata alla natura” è un'area che principalmente preserva o ripristina la natura. Le aree quasi naturali/verdi possono essere situate nel sito dell'organizzazione e possono includere tetti, facciate, sistemi di drenaggio dell'acqua o altri elementi progettati, adattati o gestiti per promuovere la biodiversità. Le aree quasi naturali possono essere situate anche al di fuori del sito dell'organizzazione se sono di proprietà o gestite dall'organizzazione e servono principalmente a promuovere la biodiversità.
A14: Uso del suolo totale [ha] | D14: =(C14-B14)/B14 -> #DIV/0!
A15: Totale superficie impermeabilizzata | D15: =(C15-B15)/B15 -> #DIV/0!
A16: Totale superficie nature-oriented on-site | D16: =(C16-B16)/B16 -> #DIV/0!
A17: Totale superficie nature-oriented off-site | D17: =(C17-B17)/B17 -> #DIV/0!
A19: Considerare non solo gli impatti locali ma anche quelli diretti e indiretti (es. tramite estrazione materie prime, catena di fornitura, produzione, trasporti e logistica, marketing e comunicazioni)

Sheet B7_M
A1: Nota - Se l'impresa opera in un settore che utilizza flussi di materiali significativi (ad esempio produzione, edilizia, imballaggio o altri), deve comunicare il flusso dei materiali rilevanti utilizzati. I dati relativi ai materiali possono essere omessi se trascurabili (es. consumabili uffici)
A3: B7 - Utilizzo delle risorse, economia circolare e gestione dei rifiuti
A4: Materiali significativi utilizzati (materie prime, materiali ausiliari, semilavorati) | B4: UdM | C4: Sede 1 - 2024 | D4: Sede 2 - 2024 | E4: Sede 1 - 2025 | F4: Sede 2 - 2025 | G4: Materiale riutilizzato/riciclato? | H4: Colonna1
A5: CONSUMO ACQUA | B5: m3
A6: Olio lubrificante | B6: kg
A7: Acciaio inox | B7: kg
A8: Acciaio | B8: kg
A9: Alluminio | B9: kg
A10: Azoto | B10: m3
A11: CO2 | B11: m3
A12: CO2 kg | B12: kg
A13: Argon liquido kg | B13: kg
A14: Ossigeno | B14: m3
A15: Gas saldatura m3 | B15: m3
A16: Gas saldatura kg | B16: kg
... A19: Verniciatura per kg | B19: kg
A26: B7 - Altre informazioni: Utilizzo delle risorse, economia circolare e gestione dei rifiuti
A27: Comunicare se sono applicati i principi dell'economia circolare e, se sì, in che modo
A39: B7 - Utilizzo delle risorse, economia circolare e gestione dei rifiuti
A40: Materiali significativi utilizzati (materie prime, materiali ausiliari, semilavorati) | B40: UdM | C40: Sede 1 - 2024 | D40: Sede 2 - 2024 | E40: TOTALE 2024 | F40: Sede 1 - 2025 | G40: Sede 2 - 2025 | H40: TOTALE 2025 | I40: Delta % 2025 - 2024
A41: CONSUMO ACQUA | B41: m3
A42: Acciaio | B42: kg
A43: Acciaio inox | B43: kg
A44: Alluminio | B44: kg
A45: Olio lubrificante | B45: kg
A46: Azoto | B46: m3
A47: CO2 | B47: m3
A48: Argon liquido | B48: kg
A49: Ossigeno | B49: m3
A50: Gas saldatura | B50: m3
A51: Filo saldatura | B51: kg
A52: Verniciatura | B52: kg
A55: B7 - Utilizzo delle risorse, economia circolare e gestione dei rifiuti
A56: Materiali significativi utilizzati (materie prime, materiali ausiliari, semilavorati) | B56: UdM | C56: Sede 1 - 2024 | D56: Sede 2 - 2024 | E56: TOTALE 2024 | F56: Sede 1 - 2025 | G56: Sede 2 - 2025 | H56: TOTALE 2025 | I56: Delta % 2025 - 2024
A57: CONSUMO ACQUA | B57: m3 | C57: =C41 -> 0 | D57: =D41 -> 0 | E57: =D57+C57 -> 0 | F57: =F41 -> 0 | G57: =G41 -> 0 | H57: =G57+F57 -> 0 | I57: =H57/E57-1 -> #DIV/0!
A58: Acciaio | B58: tons | C58: =C42/1000 -> 0 | D58: =D42/1000 -> 0 | E58: =D58+C58 -> 0 | F58: =F42/1000 -> 0 | G58: =G42/1000 -> 0 | H58: =G58+F58 -> 0 | I58: =H58/E58-1 -> #DIV/0!
A59: Acciaio inox | B59: tons | C59: =C43/1000 -> 0 | D59: =D43/1000 -> 0 | E59: =D59+C59 -> 0 | F59: =F43/1000 -> 0 | G59: =G43/1000 -> 0 | H59: =G59+F59 -> 0 | I59: =H59/E59-1 -> #DIV/0!
A60: Alluminio | B60: tons | C60: =C44/1000 -> 0 | D60: =D44/1000 -> 0 | E60: =D60+C60 -> 0 | F60: =F44/1000 -> 0 | G60: =G44/1000 -> 0 | H60: =G60+F60 -> 0 | I60: =H60/E60-1 -> #DIV/0!
A61: Olio lubrificante | B61: tons | C61: =C45/1000 -> 0 | D61: =D45/1000 -> 0 | E61: =D61+C61 -> 0 | F61: =F45/1000 -> 0 | G61: =G45/1000 -> 0 | H61: =G61+F61 -> 0 | I61: =H61/E61-1 -> #DIV/0!
A62: Gas Tecnici | B62: m3 | C62: =C46+C47+C49+C50 -> 0 | D62: =D46+D47+D49+D50 -> 0 | E62: =D62+C62 -> 0 | F62: =F46+F47+F49+F50 -> 0 | G62: =G46+G47+G49+G50 -> 0 | H62: =G62+F62 -> 0 | I62: =H62/E62-1 -> #DIV/0!
...

Sheet B6
A1: B6 - Acqua
A2: Prelievo e consumo di acqua | B2: UdM | C2: 2024 | D2: 2025
A3: Prelievo da acquedotto | K3: Il prelievo idrico si riferisce alla quantità di acqua che un'impresa preleva all'interno dei propri confini organizzativi da qualsiasi fonte durante il periodo di riferimento. In pratica, per la maggior parte delle imprese si tratta della quantità di acqua prelevata dalla rete idrica pubblica, come indicato nelle bollette. | R3: Il consumo idrico è la quantità di acqua prelevata all'interno dei confini dell'impresa che non viene scaricata o che si prevede di scaricare nuovamente nell'ambiente idrico o a terzi. Si tratta tipicamente di acqua evaporata (ad esempio, nei processi di energia termica) o di acqua incorporata nei prodotti (ad esempio, nella produzione alimentare) o di acqua per l'irrigazione - ad esempio, utilizzata in agricoltura o per innaffiare i locali dell'impresa. Calcolato come: Consumo di acqua = Acqua [prelievo + raccolta di acqua piovana - scarichi].
A4: Prelievo da pozzo
A5: Prelievo acque superficiali (es. laghi, fiumi)
A6: Prelievo di acqua da altre fonti (specificare)
A7: Totale prelievo idrico | C7: =SUM(C3:C6) -> 0 | D7: =SUM(D3:D6) -> 0
A8: La zona di prelievo è soggetta a stress idrico? | F8: WRI’s Aqueduct Water Risk Atlas
A9: Se sì, specificare la quantità di acqua prelevata in siti soggetti ad alto stress idrico
A10: Quantità di acqua scaricata
A11: Consumo di acqua | C11: =SUM(C3:C6)-C10 -> 0 | D11: =SUM(D3:D6)-D10 -> 0

Sheet B7_R
A1: Nota - i dati relativi ai rifiuti possono essere omessi se l'Organizzazione produce solo rifiuti urbani I VSME richiedono solo i totali in fondo, compilare la tabella con il dettaglio dei codici EER solo se è comodo per il calcolo o se interessa inserire un maggiore dettaglio in modo da tracciare eventuali variazioni da un anno all'altro
A3: B7 - Utilizzo delle risorse, economia circolare e gestione dei rifiuti
A4: Rifiuti (con codice EER) | B4: UdM | C4: Pericolosità | D4: Sede 1 - 2024 | E4: Sede 2 - 2024 | F4: Trattamento 2024 | G4: Sede 1 - 2025 | H4: Sede 2 - 2025 | I4: Trattamento 2025
A5: apparecchiature fuori uso 160214, diverse da quelle di cui alle voci da 160209 a 160213 | B5: kg | C5: Non pericoloso | F5: Riciclo/riutilizzo | I5: Riciclo/riutilizzo
A6: ferro e acciaio 170405 | B6: kg | C6: Non pericoloso | F6: Riciclo/riutilizzo | I6: Riciclo/riutilizzo | L6: =5673/6034-1 -> -0.059827643
A7: imballaggi in legno 150103 | B7: kg | C7: Non pericoloso | F7: Riciclo/riutilizzo | I7: Riciclo/riutilizzo | L7: =3585/2991-1 -> 0.19859579
A8: imballaggi in materiali misti 150106 | B8: kg | C8: Non pericoloso | F8: Riciclo/riutilizzo | I8: Riciclo/riutilizzo | L8: =3610/2994-1 -> 0.20574482
A9: limatura e trucioli di materiali ferrosi 120101 | B9: kg | C9: Non pericoloso | F9: Riciclo/riutilizzo | I9: Riciclo/riutilizzo
A10: polveri e particolato di materiali ferrosi 120102 | B10: kg | C10: Non pericoloso | F10: Riciclo/riutilizzo | I10: Riciclo/riutilizzo | L10: =H6+G9+B7_R!$G10+B7_R!$H10 -> 0
A11: polveri e particolato di materiali non ferrosi 120104 | B11: kg | C11: Non pericoloso | F11: Riciclo/riutilizzo | I11: Riciclo/riutilizzo
A12: rifiuti liquidi acquosi 161002, diversi da quelli di cui alla voce 16 10 01 | B12: kg | C12: Non pericoloso | F12: Smaltimento | I12: Smaltimento
A13: toner per stampa esauriti 080318, diversi da quelli di cui alla voce 080317 | B13: kg | C13: Non pericoloso | F13: Riciclo/riutilizzo | I13: Riciclo/riutilizzo
A14: oli minerali per circuiti idraulici, non clorurati 130110 | B14: kg | C14: Pericoloso | F14: Smaltimento | I14: Smaltimento
A15: oli minerali per motori, ingranaggi e lubrificazione, non clorurati 130205 | B15: kg | C15: Pericoloso | F15: Smaltimento | I15: Smaltimento
A16: oli e altre emulsioni 130802 | B16: kg | C16: Pericoloso | F16: Smaltimento | I16: Smaltimento
A17: assorbenti, materiali filtranti (inclusi filtri dell'olio non specificati altrimenti), stracci e indumenti protettivi, contaminati da sostanze pericolose 150202 | B17: kg | C17: Pericoloso | F17: Smaltimento | I17: Smaltimento
A18: apparecchiature fuori uso, contenenti componenti pericolosi (3) 160213, diversi da quelli di cui alle voci da 160209 a 160212 | B18: kg | C18: Pericoloso | F18: Smaltimento | I18: Smaltimento
A19: 150110 - imballaggi contenenti residui di sostanze pericolose o contaminati da tali sostanze | B19: kg | C19: Pericoloso | F19: Smaltimento | I19: Smaltimento
A20: 200121 - Tubi fluorescenti ed altri rifiuti contenenti mercurio | B20: kg | C20: Pericoloso | F20: Smaltimento | I20: Smaltimento
A21: 120109 - Emulsioni e soluzioni per macchinari, non contenenti alogeni | B21: kg | C21: Pericoloso | I21: Smaltimento
A22: 150110 - imballaggi contenenti residui di sostanze pericolose o contaminati da tali sostanze | B22: kg | C22: Pericoloso | I22: Smaltimento
A23: 200121 - Tubi fluorescenti ed altri rifiuti contenenti mercurio | B23: kg | C23: Pericoloso | I23: Riciclo/riutilizzo
A24: 130208 Altri oli per motori, ingranaggi e lubrificazione | B24: kg | C24: Pericoloso | I24: Riciclo/riutilizzo
A25: Imballaggi in plastica non pericolosi 150102 | B25: kg | C25: Non pericoloso | I25: Riciclo/riutilizzo
A26: Miscugli o scorie di cemento, mattoni, mattonelle e ceramiche, diverse da quelle di cui alla voce 17 01 06 170107 | B26: kg | C26: Non pericoloso | I26: Riciclo/riutilizzo
A27: Rifiuti misti dell'attività di costruzione e demolizione, diversi da quelli di cui alle voci 17 09 01, 17 09 02 e 17 09 03 170904 | B27: kg | C27: Non pericoloso | I27: Riciclo/riutilizzo
A28: Rifiuti urbani non differenziati 200301 | B28: kg | C28: Non pericoloso | I28: Smaltimento
A29: Rifiuti ingombranti 200307 | B29: kg | C29: Non pericoloso | I29: Riciclo/riutilizzo
A30: Componenti rimossi da apparecchiature fuori uso, diversi da quelli di cui alla voce 16 02 15 150216 | B30: kg | C30: Non pericoloso | I30: Riciclo/riutilizzo
A31: Rifiuti organici, contenenti sostanze pericolose 160305 | B31: kg | C31: Pericoloso | I31: Smaltimento
A33: TOTALE | D33: Sede 1 - 2024 | E33: Sede 2 - 2024 | G33: Sede 1 - 2025 | H33: Sede 2 - 2025
A34: Quantità rifiuti pericolosi
A35: Quantità rifiuti non pericolosi
A36: Totale rifiuti
A37: Quantità rifiuti destinati a riciclo o riutilizzo
A38: Quantità rifiuti destinati a smaltimento
A39: Totale rifiuti
A41: Il totale dei rifiuti per pericolosità e per trattamento deve coincidere
B48: Benacchio 2024 | C48: Stat 2024 | D48: Totale 2024 | E48: Benacchio 2025 | F48: Stat 2025 | G48: Totale 2025 | H48: Delta % 2025-2024
A49: =A34 -> Quantità rifiuti pericolosi | B49: =D34 -> 0 | C49: =E34 -> 0 | D49: =C49+B49 -> 0 | E49: =G34 -> 0 | F49: =H34 -> 0 | G49: =F49+E49 -> 0 | H49: =G49/D49-1 -> #DIV/0!
...

Sheet B8
A1: B8 - Forza lavoro: Caratteristiche generali
A3: Considerare i dati al 31/12 per la compilazione di queste tabelle
A4: Inserire i dati come headcount
A6: B8.1 - Numero dipendenti per tipologia contrattuale | B6: 2023 | C6: 2024
A7: Tempo indeterminato
A8: Tempo determinato
A9: Totale dipendenti | B9: =SUM(B7:B8) -> 0 | C9: =SUM(C7:C8) -> 0
A11: B8.2 - Numero lavoratori per genere | B11: 2023 | C11: 2024
A12: Uomo
A13: Donna
A14: Altro
A15: Non segnalato
A16: Totale dipendenti | B16: =SUM(B12:B15) -> 0 | C16: =SUM(C12:C15) -> 0
A18: B8.3 - Turnover | B18: 2023 | C18: 2024 | E18: Il turnover dei dipendenti si riferisce ai dipendenti che lasciano l'azienda volontariamente o a causa di licenziamento, pensionamento o decesso in servizio. Il tasso di turnover viene calcolato come: (Numero di dipendenti in uscita durante l'anno di riferimento / Media dei dipendenti durante l'anno di riferimento) x 100
A19: Numero totale di dipendenti in uscita
A20: Media di dipendenti durante l'anno
A21: Tasso di turnover | B21: =(B19/B20)*100 -> #DIV/0! | C21: =(C19/C20)*100 -> #DIV/0!
A23: B8.4 - Numero di dipendenti per Stato | B23: 2023 | C23: 2024
A24: Stato #1
A25: Stato #2
A26: Stato #3
A27: Stato #4
A28: Stato #5
A29: Totale dipendenti | B29: =SUM(B24:B28) -> 0 | C29: =SUM(C24:C28) -> 0

Sheet B9-C6-C7
A1: B9 - Forza lavoro: Salute e sicurezza
B2: 2024 | E2: 2025
A3: B9 - Infortuni sul lavoro | B3: Sede 1 - 2024 | C3: Sede 2 - 2024 | D3: Totale | E3: Sede 1 - 2025 | F3: Sede 2 - 2025 | G3: Totale
A4: Numero totale infortuni sul lavoro | D4: =C4+B4 -> 0 | G4: =F4+E4 -> 0
A5: di cui con gravi conseguenze | D5: =C5+B5 -> 0 | G5: =F5+E5 -> 0
A6: N.decessi da infortuni sul lavoro | D6: =C6+B6 -> 0 | G6: =F6+E6 -> 0
A7: N.decessi da malattia professionale | D7: =C7+B7 -> 0 | G7: =F7+E7 -> 0
A8: N. casi di malattia professionale registrabili | D8: =C8+B8 -> 0 | G8: =F8+E8 -> 0
A9: TOT. ore ordinarie lavorate | D9: =C9+B9 -> 0 | G9: =F9+E9 -> 0
A10: TOT. ore straordinarie lavorate | D10: =C10+B10 -> 0 | G10: =F10+E10 -> 0
A11: TOT. ore lavorate | B11: =B9+B10 -> 0 | C11: =C9+C10 -> 0 | D11: =D9+D10 -> 0 | E11: =E9+E10 -> 0 | F11: =F9+F10 -> 0 | G11: =G9+G10 -> 0
A12: TOT. ore perse per infortunio | B12: ='[1]B9-C6-C7'!B11 -> 0 | C12: ='[2]HR B9-C6-C7'!B11 -> 0 | D12: =C12+B12 -> 0 | E12: ='[1]B9-C6-C7'!C11 -> 0 | F12: ='[2]HR B9-C6-C7'!C11 -> 0 | G12: =F12+E12 -> 0
A13: % ore perse sul totale | B13: =B12/B11 -> #DIV/0! | C13: =C12/C11 -> #DIV/0! | D13: =D12/D11 -> #DIV/0! | E13: =E12/E11 -> #DIV/0! | F13: =F12/F11 -> #DIV/0! | G13: =G12/G11 -> #DIV/0!
A14: Tasso di infortunio (n.infortuni/totale ore lavorative)*200.000 | B14: =(B4/B9)*200000 -> #DIV/0! | C14: =(C4/C9)*200000 -> #DIV/0! | D14: =(D4/D9)*200000 -> #DIV/0! | E14: =(E4/E9)*200000 -> #DIV/0! | F14: =(F4/F9)*200000 -> #DIV/0! | G14: =(G4/G9)*200000 -> #DIV/0!
A16: C6 - Ulteriori informazioni sulla forza lavoro - Politiche e processi in materia di diritti umani
A17: C6 - Politiche e processi in materia di diritti umani | B17: Sede 1 - 2024 | C17: Sede 2 - 2024 | D17: Sede 1 - 2025 | E17: Sede 2 - 2025
A18: L'impresa ha un codice di condotta o una politica sui diritti umani per il proprio personale?
A19: Se sì, riguarda:
A20: i. il lavoro minorile
A21: ii. Il lavoro forzato
A22: iii. la tratta di essere umani
A23: iv. la discriminazione
A24: v. la prevenzione degli infortuni
A25: vi. Altro (Se sì, specificare)
A27: L'impresa dispone di un meccanismo di gestione dei reclami per la propria forza lavoro?
A29: C7 - Gravi incidenti negativi in materia di diritti umani
A30: C7 - Gravi incidenti negativi in materia di diritti umani | B30: Sede 1 - 2024 | C30: Sede 2 - 2024 | D30: Sede 1 - 2025 | E30: Sede 2 - 2025
A31: L'impresa ha confermato episodi di incidenti nella propria forza lavoro relativi a:
A32: i. il lavoro minorile
A33: ii. Il lavoro forzato
A34: iii. la tratta di essere umani
A35: iv. la discriminazione
A36: v. Altro (Se sì, specificare)
A37: Se sì, specificare azioni intraprese
A39: L'impresa è a conoscenza di incidenti confermati che coinvolgono i lavoratori della catena del valore, le comunità interessate, i consumatori e gli utenti finali?
A40: Se sì, specificare

Sheet B8-C5
A1: B8 - Forza lavoro: Caratteristiche generali
A3: Considerare i dati al 31/12 per la compilazione di queste tabelle
A4: Inserire i dati come headcount
B5: 2024 | E5: 2025
A6: B8.1 - Numero dipendenti per tipologia contrattuale | B6: Sede 1 - 2024 | C6: Sede 2 - 2024 | D6: Totale | E6: Sede 1 - 2025 | F6: Sede 2 - 2025 | G6: Totale
A7: Tempo indeterminato | D7: =B7+C7 -> 0 | G7: =E7+F7 -> 0
A8: Tempo determinato | D8: =B8+C8 -> 0 | G8: =E8+F8 -> 0
A9: Apprendistato | D9: =B9+C9 -> 0 | G9: =E9+F9 -> 0
A10: Totale dipendenti | B10: =SUM(B7:B9) -> 0 | C10: =SUM(C7:C9) -> 0 | D10: =B10+C10 -> 0 | E10: =SUM(E7:E9) -> 0 | F10: =SUM(F7:F9) -> 0 | G10: =E10+F10 -> 0
B12: 2024 | E12: 2025
A13: B8.2 - Numero lavoratori per genere | B13: Sede 1 - 2024 | C13: Sede 2 - 2024 | D13: Totale | E13: Sede 1 - 2025 | F13: Sede 2 - 2025 | G13: Totale
A14: Uomo | D14: =B14+C14 -> 0 | G14: =E14+F14 -> 0
A15: Donna | D15: =B15+C15 -> 0 | G15: =E15+F15 -> 0
A16: Altro | D16: =B16+C16 -> 0 | G16: =E16+F16 -> 0
A17: Non segnalato | D17: =B17+C17 -> 0 | G17: =E17+F17 -> 0
A18: Totale dipendenti | B18: =SUM(B14:B17) -> 0 | C18: =SUM(C14:C17) -> 0 | D18: =SUM(D14:D17) -> 0 | E18: =SUM(E14:E17) -> 0 | F18: =SUM(F14:F17) -> 0 | G18: =SUM(G14:G17) -> 0
B20: 2024 | E20: 2025
A21: B8.3 - Turnover | B21: Sede 1 - 2024 | C21: Sede 2 - 2024 | D21: Totale | E21: Sede 1 - 2025 | F21: Sede 2 - 2025 | G21: Totale | I21: Il turnover dei dipendenti si riferisce ai dipendenti che lasciano l'azienda volontariamente o a causa di licenziamento, pensionamento o decesso in servizio. Il tasso di turnover viene calcolato come: (Numero di dipendenti in uscita durante l'anno di riferimento / Media dei dipendenti durante l'anno di riferimento) x 100
A22: Numero totale di dipendenti in uscita | D22: =B22+C22 -> 0 | G22: =E22+F22 -> 0
A23: Numero di dipendenti ad inizio periodo | D23: =B23+C23 -> 0 | G23: =E23+F23 -> 0
A24: Numero di dipendenti a fine periodo | D24: =B24+C24 -> 0 | G24: =E24+F24 -> 0
A25: Media di dipendenti durante l'anno
A26: Tasso di turnover | B26: =(B22/B25)*100 -> #DIV/0! | C26: =(C22/C25)*100 -> #DIV/0! | D26: =(D22/D25)*100 -> #DIV/0! | E26: =(E22/E25)*100 -> #DIV/0! | F26: =(F22/F25)*100 -> #DIV/0! | G26: =(G22/G25)*100 -> #DIV/0!
B28: 2024 | E28: 2025
A29: B8.4 - Numero di dipendenti per Stato | B29: Sede 1 - 2024 | C29: Sede 2 - 2024 | D29: Totale | E29: Sede 1 - 2025 | F29: Sede 2 - 2025 | G29: Totale
A30: Italia | D30: =B30+C30 -> 0 | G30: =E30+F30 -> 0
A31: Stato #2 | D31: =B31+C31 -> 0 | G31: =E31+F31 -> 0
A32: Stato #3 | D32: =B32+C32 -> 0 | G32: =E32+F32 -> 0
A33: Stato #4 | D33: =B33+C33 -> 0 | G33: =E33+F33 -> 0
A34: Stato #5 | D34: =B34+C34 -> 0 | G34: =E34+F34 -> 0
A35: Totale dipendenti | B35: =SUM(B30:B34) -> 0 | C35: =SUM(C30:C34) -> 0 | D35: =SUM(D30:D34) -> 0 | E35: =SUM(E30:E34) -> 0 | F35: =SUM(F30:F34) -> 0 | G35: =SUM(G30:G34) -> 0
A37: C5 - Forza lavoro: Ulteriori caratteristiche
B39: 2024 | E39: 2025
A40: C5.1 - Diversità management | B40: Sede 1 - 2024 | C40: Sede 2 - 2024 | D40: Totale | E40: % | F40: Sede 1 - 2025 | G40: Sede 2 - 2025 | H40: Totale | I40: %
A41: Numero membri di sesso femminile | D41: =B41+C41 -> 0 | E41: =D41/D43 -> #DIV/0! | H41: =F41+G41 -> 0 | I41: =H41/H43 -> #DIV/0! | K41: Il livello manageriale è considerato il livello inferiore al consiglio di amministrazione.
A42: Numero membri di sesso maschile | D42: =B42+C42 -> 0 | E42: =D42/D43 -> #DIV/0! | H42: =F42+G42 -> 0 | I42: =H42/H43 -> #DIV/0!
A43: Totale | D43: =SUM(D41:D42) -> 0 | E43: =SUM(E41:E42) -> #DIV/0! | H43: =SUM(H41:H42) -> 0 | I43: =SUM(I41:I42) -> #DIV/0!
A44: Indice di diversità di genere | B44: =B41/B42 -> #DIV/0! | C44: =C41/C42 -> #DIV/0! | D44: =D41/D42 -> #DIV/0! | E44: =E41/E42 -> #DIV/0! | F44: =E41/E42 -> #DIV/0! | G44: =F41/F42 -> #DIV/0! | H44: =H41/H42 -> #DIV/0! | I44: =I41/I42 -> #DIV/0!
B46: 2024 | E46: 2025
A47: C5.2 - Forza lavoro esterna | B47: Sede 1 - 2024 | C47: Sede 2 - 2024 | D47: Totale | E47: Sede 1 - 2025 | F47: Sede 2 - 2025 | G47: Totale
...

Sheet B9
A1: B9 - Forza lavoro: Salute e sicurezza
A2: B9 - Infortuni sul lavoro | B2: 2023 | C2: 2024
A3: Numero totale infortuni sul lavoro
A4: di cui con gravi conseguenze
A5: N.decessi da infortuni sul lavoro
A6: N.decessi da malattia professionale
A7: N. casi di malattia professionale registrabili
A8: TOT. ore ordinarie lavorate
A9: TOT. ore straordinarie lavorate
A10: TOT. ore lavorate | B10: =B8+B9 -> 0 | C10: =C8+C9 -> 0
A11: TOT. ore perse per infortunio
A12: % ore perse sul totale | B12: =B11/B10 -> #DIV/0! | C12: =C11/C10 -> #DIV/0!
A13: Tasso di infortunio (n.infortuni/totale ore lavorative)*200.000 | B13: =(B3/B8)*200000 -> #DIV/0! | C13: =(C3/C8)*200000 -> #DIV/0!

Sheet B10
A1: B10 - Retribuzione, contrattazione collettiva e formazione
A3: B10.1 - Rapporto tra salario di ingresso e salario minimo | B3: Sede 1 - 2024 | C3: Sede 2 - 2024 | D3: Sede 1 - 2025 | E3: Sede 2 - 2025 | G3: Per "salario di ingresso" si intende il salario a tempo pieno della categoria occupazionale più bassa. I salari dei tirocinanti e degli apprendisti non devono essere considerati nell'identificazione del salario di ingresso dell'impresa.
A4: Salario di ingresso | G4: Per "salario minimo" si intende il compenso minimo di lavoro per ora, o altra unità di tempo, consentito dalla legge. A seconda del Paese, il salario minimo può essere stabilito direttamente dalla legge o attraverso accordi di contrattazione collettiva.
A5: Salario minimo
A6: Indice | B6: =B4/B5 -> #DIV/0! | C6: =C4/C5 -> #DIV/0! | D6: =D4/D5 -> #DIV/0! | E6: =E4/E5 -> #DIV/0!
A7: Percentage | B7: =(B4-B5)/B5 -> #DIV/0! | C7: =(C4-C5)/C5 -> #DIV/0! | D7: =(D4-D5)/D5 -> #DIV/0! | E7: =(E4-E5)/E5 -> #DIV/0!
A9: B10.2 - Pay Gap* | B9: Sede 1 - 2024 | C9: Sede 2 - 2024 | D9: Sede 1 - 2025 | E9: Sede 2 - 2025 | G9: *L'impresa può omettere questa informazione quando l'organico è inferiore a 150 dipendenti.
A10: Retribuzione lorda oraria media per i dipendenti di sesso maschile | G10: La retribuzione lorda oraria è data dalla somma su base settimanale/annuale di: (a) stipendio base (b) indennità, bonus, commissioni, altre forme di pagamenti variabili in denaro (c) altri benefit quali automobili, assicurazione sanitaria privata, assicurazione sulla vita e programmi di benessere divisa per le ore medie lavorate settimanalmente/annualmente
A11: Retribuzione lorda oraria media per i dipendenti di sesso femminile
A12: Gender pay gap | B12: =(B10-B11)/B10 -> #DIV/0! | C12: =(C10-C11)/C10 -> #DIV/0! | D12: =(D10-D11)/D10 -> #DIV/0! | E12: =(E10-E11)/E10 -> #DIV/0!
A14: B10.3 - Contrattazione collettiva | B14: Sede 1 - 2024 | C14: Sede 2 - 2024 | D14: Sede 1 - 2025 | E14: Sede 2 - 2025
A15: Numero di dipendenti coperti da contratti collettivi
A16: Totale dipendenti
A17: % copertura | B17: =B15/B16 -> #DIV/0! | C17: =C15/C16 -> #DIV/0! | D17: =D15/D16 -> #DIV/0! | E17: =E15/E16 -> #DIV/0!
A19: B10.4 - Ore di formazione per genere (obbligatoria e non) | B19: Sede 1 - 2024 | C19: Sede 2 - 2024 | D19: Sede 1 - 2025 | E19: Sede 2 - 2025
A20: Ore totali di formazione per gli uomini
A21: Ore totali di formazione per le donne
A22: FORMAZIONE HSE-E BEN | G22: Stat aveva dato le ore medie di formazione calcolate da loro
A23: Ore totali di formazione | B23: =SUM(B20:B22) -> 0 | C23: =SUM(C20:C22) -> 0 | D23: =SUM(D20:D22) -> 0 | E23: =SUM(E20:E22) -> 0 | G23: non corrispondono
A24: Ore medie di formazione per gli uomini
A25: Ore medie di formazione per le donne
A26: Ore medie di formazione per altro genere
A27: Ore medie di formazione per dipendente | B27: =B23/'B8-C5'!B18 -> #DIV/0! | C27: =C23/'B8-C5'!C18 -> #DIV/0! | D27: =D23/'B8-C5'!E18 -> #DIV/0! | E27: =E23/'B8-C5'!F18 -> #DIV/0!

Sheet B11
A1: B11 - Condanne e sanzioni per corruzione e concussione
B2: 2023 | C2: 2024
A3: Numero di condanne
A4: Importo totale sanzioni per violazione delle leggi anticorruzione e anticoncussione

Sheet B11-C8-C9
A1: B11 - Condanne e sanzioni per corruzione e concussione
B2: 2024 | C2: 2025
A3: Numero di condanne
A4: Importo totale sanzioni per violazione delle leggi anticorruzione e anticoncussione
A6: C8 - Ricavi in alcuni settori
B7: Ricavi [€] 2024 | C7: Ricavi [€] 2025
A8: Se l'impresa opera in uno o più dei seguenti settori, deve indicare i relativi ricavi:
A9: a) armi controverse come mine antiuomo, munizioni a grappolo, armi chimiche e armi biologiche
A10: b) coltivazione e produzione di tabacco
A11: c) settore dei combustibili fossili (carbone, petrolio e gas)*
A12: d) produzione di sostanze chimiche (ad es. pesticidi o altri prodotti agrochimici)
A14: *l'impresa produce ricavi dall'esplorazione, dall'estrazione mineraria, dall'estrazione, dalla produzione, dalla trasformazione, dallo stoccaggio, dalla raffinazione o dalla distribuzione, compresi il trasporto, lo stoccaggio e il commercio, di combustibili fossili
A18: C9 - Diversità organo di governance
B19: 2024 | D19: 2025
A20: C9 - Diversità organo di governance | B20: Sede 1 - 2024 | C20: Sede 2 - 2024 | D20: Sede 1 - 2025 | E20: Sede 2 - 2025
A21: Numero membri di sesso femminile | G21: L'organo di governance si riferisce alla massima autorità decisionale di una impresa.
A22: Numero membri di sesso maschie
A23: Totale | B23: =SUM(B21:B22) -> 0 | C23: =SUM(C21:C22) -> 0 | D23: =SUM(D21:D22) -> 0 | E23: =SUM(E21:E22) -> 0
A24: Indice di diversità di genere | B24: =B21/B22 -> #DIV/0! | C24: =C21/C22 -> #DIV/0! | D24: =D21/D22 -> #DIV/0! | E24: =E21/E22 -> #DIV/0!

Sheet Elenchi
A1: Sì | B1: Pericoloso | C1: Breve | D1: Elevato | E1: Low (<10%)
A2: No | B2: Non pericoloso | C2: Medio | D2: Medio | E2: Low-medium (10-20%)
B3: Riciclo/riutilizzo | C3: Lungo | D3: Basso | E3: Medium-high (20-40%)
B4: Smaltimento | E4: High (40-80%)
E5: Extremely high (>80%)

Sheet C2
A1: C2 - Descrizione delle pratiche, politiche e iniziative future per la transizione verso un'economia più sostenibile
B2: Se avete risposto SÌ alle pratiche/alle politiche esistenti/alle iniziative future di cui all'informativa B2, descrivetele brevemente insieme alle azioni che ne conseguono. (Nel caso in cui la pratica/politica/iniziativa futura riguardi fornitori o clienti, l'impresa dovrà farne menzione) | C2: Se avete risposto SÌ alle iniziative/obiettivi futuri di cui all'informativa B2, specificateli. | D2: Indicare il livello dirigenziale più alto nell'impresa responsabile della loro attuazione [se presente].
A3: Cambiamento climatico
A4: Inquinamento
A5: Acqua e risorse marine
A6: Biodiversità ed ecosistemi
A7: Economia circolare
A8: Forza lavoro propria
A9: Lavoratori nella catena del valore
A10: Comunità interessate
A11: Consumatori e utenti finali
A12: Condotta aziendale

Sheet C3
A1: C3 - Obiettivi di riduzione GHG
A2: Categoria GHG Protocol | B2: UdM | C2: Anno base | D2: Anno target | E2: ∆% | F2: Azioni per il raggiungimento dell'obiettivo
E3: =(D3-C3)/C3 -> #DIV/0!
E4: =(D4-C4)/C4 -> #DIV/0!
E5: =(D5-C5)/C5 -> #DIV/0!
A7: (per aziende che operano in settori ad alto impatto climatico)
A8: L'azienda ha adottato un piano di transizione per la mitigazione dei cambiamenti climatici?
A9: Sì: fornire informazioni a riguardo, compresa una spiegazione di come sta contribuendo alla riduzione delle emissioni di gas serra.
A10: No: indicare se e quando lo adotterà

Sheet C4
A1: C4 – Rischi climatici
A2: L'azienda ha individuato pericoli ed eventi di transizione legati al clima che creano rischi climatici rilevanti per l'impresa?
A3: Se sì: compilare la seguente tabella
A4: Descrizione pericolo/evento di transizione legato al clima | B4: Entità impatto | C4: Orizzonte temporale pericolo/evento | D4: Azioni di adattamento | E4: Potenziale effetto negativo su risultati finanziari o su operazioni commerciali | F4: Orizzonte temporale effetto | G4: Rischio effetto

Sheet C5
A1: C5 - Forza lavoro: Ulteriori caratteristiche
A3: C5.1 - Diversità management | B3: 2023 | C3: % | D3: 2024 | E3: %
A4: Numero membri di sesso femminile | C4: =B4/B6 -> #DIV/0! | E4: =D4/D6 -> #DIV/0! | G4: Il livello manageriale è considerato il livello inferiore al consiglio di amministrazione.
A5: Numero membri di sesso maschie | C5: =B5/B6 -> #DIV/0! | E5: =D5/D6 -> #DIV/0!
A6: Totale | B6: =SUM(B4:B5) -> 0 | C6: =SUM(C4:C5) -> #DIV/0! | D6: =SUM(D4:D5) -> 0 | E6: =SUM(E4:E5) -> #DIV/0!
A7: Indice di diversità di genere | B7: =B4/B5 -> #DIV/0! | D7: =D4/D5 -> #DIV/0!
A9: C5.2 - Forza lavoro esterna | B9: 2023 | C9: 2024
A10: Lavoratori autonomi
A11: Lavoratori interinali
A12: Altro (specificare)
A13: Totale | B13: =SUM(B10:B11) -> 0 | C13: =SUM(C10:C11) -> 0
A15: D5.3 - Numero dipendenti per inquadramento | B15: 2023 | C15: 2024
A16: Dirigenti
A17: Quadri
A18: Impiegati
A19: Operai
A20: Totale | B20: =SUM(B16:B19) -> 0 | C20: =SUM(C16:C19) -> 0
A22: D5.4 - Numero dipendenti per età | B22: 2023 | C22: 2024
A23: <30 ANNI
A24: 30-50 ANNI
A25: >50 ANNI
A26: Totale | B26: =SUM(B23:B25) -> 0 | C26: =SUM(C23:C25) -> 0
A28: D5.5 - Numero dipendenti per orario lavorativo | B28: 2023 | C28: 2024
A29: Full-time
A30: Part-time
A31: Totale | B31: =SUM(B29:B30) -> 0 | C31: =SUM(C29:C30) -> 0
A33: D5.6 - Numero dipendenti per anzianità aziendale | B33: 2023 | F33: 2024
B34: <2 ANNI | C34: 2-5 ANNI | D34: >5 ANNI | E34: TOTALE | F34: <2 ANNI | G34: 2-5 ANNI | H34: >5 ANNI | I34: TOTALE
A35: Dirigenti | E35: =SUM(B35:D35) -> 0 | I35: =SUM(F35:H35) -> 0
A36: Quadri | E36: =SUM(B36:D36) -> 0 | I36: =SUM(F36:H36) -> 0
A37: Impiegati | E37: =SUM(B37:D37) -> 0 | I37: =SUM(F37:H37) -> 0
A38: Operai | E38: =SUM(B38:D38) -> 0 | I38: =SUM(F38:H38) -> 0
A39: Totale | B39: =SUM(B35:B38) -> 0 | C39: =SUM(C35:C38) -> 0 | D39: =SUM(D35:D38) -> 0 | E39: =SUM(E35:E38) -> 0 | F39: =SUM(F35:F38) -> 0 | G39: =SUM(G35:G38) -> 0 | H39: =SUM(H35:H38) -> 0 | I39: =SUM(I35:I38) -> 0

Sheet C6
A1: C6 - Ulteriori informazioni sulla forza lavoro - Politiche e processi in materia di diritti umani
A2: C6 - Politiche e processi in materia di diritti umani | B2: 2023 | C2: 2024
A3: L'impresa ha un codice di condotta o una politica sui diritti umani per il proprio personale?
A4: Se sì, riguarda:
A5: i. il lavoro minorile
A6: ii. Il lavoro forzato
A7: iii. la tratta di essere umani
A8: iv. la discriminazione
A9: v. la prevenzione degli infortuni
A10: vi. Altro (Se sì, specificare)
A12: L'impresa dispone di un meccanismo di gestione dei reclami per la propria forza lavoro?

Sheet C7
A1: C7 - Gravi incidenti negativi in materia di diritti umani
A2: C7 - Gravi incidenti negativi in materia di diritti umani | B2: 2023 | C2: 2024
A3: L'impresa ha confermato episodi di incidenti nella propria forza lavoro relativi a:
A4: i. il lavoro minorile
A5: ii. Il lavoro forzato
A6: iii. la tratta di essere umani
A7: iv. la discriminazione
A8: v. Altro (Se sì, specificare)
A9: Se sì, specificare azioni intraprese
A11: L'impresa è a conoscenza di incidenti confermati che coinvolgono i lavoratori della catena del valore, le comunità interessate, i consumatori e gli utenti finali?
A12: Se sì, specificare

Sheet C8
A1: C8 - Ricavi in alcuni settori
B2: Ricavi [€] 2023 | C2: Ricavi [€] 2024
A3: Se l'impresa opera in uno o più dei seguenti settori, deve indicare i relativi ricavi:
A4: a) armi controverse come mine antiuomo, munizioni a grappolo, armi chimiche e armi biologiche
A5: b) coltivazione e produzione di tabacco
A6: c) settore dei combustibili fossili (carbone, petrolio e gas)*
A7: d) produzione di sostanze chimiche (ad es. pesticidi o altri prodotti agrochimici)
A9: *l'impresa produce ricavi dall'esplorazione, dall'estrazione mineraria, dall'estrazione, dalla produzione, dalla trasformazione, dallo stoccaggio, dalla raffinazione o dalla distribuzione, compresi il trasporto, lo stoccaggio e il commercio, di combustibili fossili

Sheet C9
A1: C9 - Diversità organo di governance
A2: C9 - Diversità organo di governance | B2: 2023 | C2: % | D2: 2024 | E2: %
A3: Numero membri di sesso femminile | C3: =B3/B5 -> #DIV/0! | E3: =D3/D5 -> #DIV/0! | G3: L'organo di governance si riferisce alla massima autorità decisionale di una impresa.
A4: Numero membri di sesso maschie | C4: =B4/B5 -> #DIV/0! | E4: =D4/D5 -> #DIV/0!
A5: Totale | B5: =SUM(B3:B4) -> 0 | C5: =SUM(C3:C4) -> #DIV/0! | D5: =SUM(D3:D4) -> 0 | E5: =SUM(E3:E4) -> #DIV/0!
A6: Indice di diversità di genere | B6: =B3/B4 -> #DIV/0! | D6: =D3/D4 -> #DIV/0!
