Workbook

Sheet Diligèa
A1: B1 - Basis for preparation
A2: A cura di Diligèa
A3: Opzione
A4: Informazioni omesse in quanto ritenute riservate o sensibili?
A5: Perimetro rendicontazione

Sheet B1
A1: B1 - Basis for preparation
A2: Ragione sociale
A3: Codice NACE/ATECO
A5: Sedi
A6: Indirizzo
A7: Codice postale
A8: Città
A9: Paese
A10: Coordinate (geolocalizzazione)
A12: Dimensione
A13: Totale degli attivi
A14: Fatturato
... A19: Breve descrizione

Sheet B2
A1: B2 - Pratiche, politiche e iniziative future per la transizione verso un'economia più sostenibile
A3: Cambiamento climatico
A4: Inquinamento
A5: Acqua e risorse marine
A6: Biodiversità ed ecosistemi
A7: Economia circolare
A8: Forza lavoro propria
A9: Lavoratori nella catena del valore
A10: Comunità interessate
A11: Consumatori e utenti finali
A12: Condotta aziendale

Sheet B2-C2
A1: B2 - Pratiche, politiche e iniziative future per la transizione verso un'economia più sostenibile
A3: Cambiamento climatico
A4: Inquinamento
A5: Acqua e risorse marine
A6: Biodiversità ed ecosistemi
A7: Economia circolare
A8: Forza lavoro propria
A9: Lavoratori nella catena del valore
A10: Comunità interessate
A11: Consumatori e utenti finali
A12: Condotta aziendale
A14: C2 - Descrizione delle pratiche, politiche e iniziative future per la transizione verso un'economia più sostenibile
... A25: Condotta aziendale

Sheet C1
A1: C1 – Strategia: modello di business e iniziative relative alla sostenibilità
A2: Descrizione dei principali gruppi di prodotti e/o servizi offerti
A3: Descrizione dei principali mercati in cui opera l'impresa (ad esempio B2B, vendita all'ingrosso, vendita al dettaglio, paesi)
A4: Descrizione delle principali relazioni commerciali (ad esempio fornitori chiave, clienti, canali di distribuzione e consumatori)
A5: La strategia presenta elementi chiave che riguardano o influenzano questioni di sostenibilità?
A6: Se sì, fornire una breve descrizione di tali elementi chiave

Sheet CarbonFootprint
A1: GHG category | C1: Quantità TOT 2024 | E1: 2024 | F1: nome file | G1: Stat 2024 | H1: nome file | I1: 2025 | J1: Stat 2025
A2: 1.1 - Stationary combustion sources | C2: 371686 | E2: 182395 | F2: Estratto monitoraggio consumi | G2: 189291 | H2: Monitoraggi 2024 | I2: 152490 | J2: 106949
A3: 1.1 - Stationary combustion sources | C3: 856373.65 | E3: 856373.65 | F3: Estratto Energia autoprodotta | I3: 1150012 | J3: 0
A4: 1.3 - Mobile combustion | C4: 18575.21 | E4: 11811.97 | F4: Carburante x Achille (non assegnati + proprietà) | G4: 6763.24 | H4: Totale carburante | I4: 12800.53 | J4: 2904
A5: 1.3 - Mobile combustion | C5: 4848.71 | G5: 4848.71 | H5: Totale carburante
A6: 2.1 - Electricity consumption | C6: 4873436.6 | E6: 3204360.6 | F6: Estratto monitoraggio consumi | G6: 1669076 | H6: Monitoraggi 2024 | I6: 3063397 | J6: 1843812
A7: 3.1 - ACQUISTI | C7: 1880 | E7: 1880 | F7: Estratto monitoraggio consumi | I7: 1970 | J7: 533
A8: 3.1 - ACQUISTI | C8: 50197.3 | E8: 31524 | F8: Copia di impatto trasporti con tipo MP | G8: 18673.3 | H8: OLIO-GAS-FILI 2024 | I8: 25983.6 | J8: 15436
A9: 3.1 - ACQUISTI | C9: 180444 | E9: 95221 | F9: Copia di impatto trasporti con tipo MP | G9: 85223 | H9: MP 2024 - con spostamenti | I9: 130000 | J9: 126068
A10: 3.1 - ACQUISTI | C10: 24821539 | E10: 15752937 | F10: Copia di impatto trasporti con tipo MP | G10: 9068602 | H10: MP 2024 - con spostamenti | I10: 22037539 | J10: 7085186
A11: 3.1 - ACQUISTI | C11: 389208 | E11: 370234 | F11: Copia di impatto trasporti con tipo MP | G11: 18974 | H11: MP 2024 - con spostamenti | I11: 426529.26 | J11: 9165
A12: 3.1 - ACQUISTI | C12: 46788 | E12: 46788 | F12: Copia di impatto trasporti con tipo MP | I12: 28666 | J12: 0
A13: 3.1 - ACQUISTI | C13: 23840 | E13: 23840 | F13: Copia di impatto trasporti con tipo MP | I13: 42135 | J13: 0
A14: 3.1 - ACQUISTI | C14: 8017 | G14: 8017 | H14: OLIO-GAS-FILI 2024 | J14: 2970
A15: 3.1 - ACQUISTI | C15: 81973.46 | E15: 55486.46 | F15: Consumo argon | G15: 26487 | H15: OLIO-GAS-FILI 2024 | I15: 46275 | J15: 13163
A16: 3.1 - ACQUISTI | C16: 5343 | E16: 2461 | F16: Copia di impatto trasporti con tipo MP | G16: 2882 | H16: OLIO-GAS-FILI 2024 | I16: 180 | J16: 43.6
A17: 3.1 - ACQUISTI | C17: 2812 | E17: 2765 | F17: Copia di impatto trasporti con tipo MP | G17: 47 | H17: OLIO-GAS-FILI 2024 | I17: 1800 | J17: 8.75
A18: 3.1 - ACQUISTI | C18: 1899 | F18: Copia di impatto trasporti con tipo MP | G18: 1899 | H18: OLIO-GAS-FILI 2024
A19: 3.1 - ACQUISTI | C19: 117250 | E19: 105000 | F19: Copia di impatto trasporti con tipo MP | G19: 12250 | H19: OLIO-GAS-FILI 2024 | I19: 69350 | J19: 11950
A20: 3.1 - ACQUISTI | C20: 271421.51 | E20: 271421.51 | F20: Verniciatura 2024 v2
A21: 3.1 - ACQUISTI | C21: 25100 | G21: 25100 | H21: email | J21: 24900
A22: 3.5 - RIFIUTI | C22: 856 | E22: 231 | F22: Estratto rifiuti e formulario 2024 | G22: 625 | H22: Analisi quantitativi rifiuti | I22: 0 | J22: 8973
A23: 3.5 - RIFIUTI | C23: 139300 | E23: 100 | F23: Estratto rifiuti e formulario 2024 | G23: 139200 | H23: Analisi quantitativi rifiuti | I23: 0 | J23: 114730
A24: 3.5 - RIFIUTI | C24: 39140 | E24: 39140 | F24: Estratto rifiuti e formulario 2024 | G24: 0 | H24: Analisi quantitativi rifiuti | I24: 50530 | J24: 13330
A25: 3.5 - RIFIUTI | C25: 131830 | E25: 49740 | F25: Estratto rifiuti e formulario 2024 | G25: 82090 | H25: Analisi quantitativi rifiuti | I25: 49650 | J25: 69200
A26: 3.5 - RIFIUTI | C26: 49370 | E26: 49370 | F26: Estratto rifiuti e formulario 2024 | I26: 52730 | J26: 0
A27: 3.5 - RIFIUTI | C27: 8459287 | E27: 5733217 | F27: Estratto rifiuti e formulario 2024 | G27: 2726070 | H27: Analisi quantitativi rifiuti | I27: 5398816 | J27: 3249984
A28: 3.5 - RIFIUTI | C28: 177630 | E28: 134870 | F28: Estratto rifiuti e formulario 2024 | G28: 42760 | H28: Analisi quantitativi rifiuti | I28: 90260 | J28: 35120
A29: 3.5 - RIFIUTI | C29: 26950 | E29: 26950 | F29: Estratto rifiuti e formulario 2024 | I29: 31150 | J29: 9160
A30: 3.5 - RIFIUTI | C30: 19 | E30: 19 | F30: Estratto rifiuti e formulario 2024 | I30: 0 | J30: 0
A31: 3.5 - RIFIUTI | C31: 3260 | E31: 3260 | F31: Estratto rifiuti e formulario 2024 | I31: 970 | J31: 0
A32: 3.5 - RIFIUTI | C32: 4940 | E32: 4940 | F32: Estratto rifiuti e formulario 2024 | I32: 7740 | J32: 4000
A33: 3.5 - RIFIUTI | C33: 13630 | E33: 13630 | F33: Estratto rifiuti e formulario 2024 | I33: 7350 | J33: 0
A34: 3.5 - RIFIUTI | C34: 2815 | E34: 2815 | F34: Estratto rifiuti e formulario 2024 | H34: Analisi quantitativi rifiuti | I34: 240 | J34: 1520
A35: 3.5 - RIFIUTI | C35: 34 | E35: 34 | F35: Estratto rifiuti e formulario 2024 | I35: 0 | J35: 0
A36: 3.5 - RIFIUTI | C36: 2330 | G36: 2330 | H36: Analisi quantitativi rifiuti | I36: 0 | J36: 100
A37: 3.5 - RIFIUTI | C37: 815 | G37: 815 | H37: Analisi quantitativi rifiuti | I37: 0 | J37: 15
A38: 3.7 - Commuting | C38: 1912910 | E38: 851000 | F38: Distanza casa lavoro dip | G38: 1061910 | H38: Tragitto casa lavoro
A39: 3.7 - Commuting | C39: 55890 | G39: 55890 | H39: Tragitto casa lavoro
A40: 3.4 - Transport in | C40: 4274230.7 | E40: 2926471.6 | F40: Copia di impatto trasporti con tipo MP | G40: 1347759.1 | H40: MP 2024 - con spostamenti
...

Sheet B3-C3-C4
A1: B3 - Energia e emissioni di gas a effetto serra
A2: B3 - Energia e emissioni di gas a effetto serra | C2: 2024 | D2: Stat 2024 | E2: 2025 | F2: Stat 2025
A3: Energia elettrica acquistata senza GdO | C3: 3204360.6 | D3: 1669076 | E3: =CarbonFootprint!I6 | F3: =CarbonFootprint!J6
A4: Energia elettrica acquistata con GdO
A5: Energia elettrica autoprodotta da fonti rinnovabili | C5: 856373.65 | E5: =CarbonFootprint!I3 | F5: =CarbonFootprint!J3
A6: Benzina per autotrazione | D6: 4848.71 | E6: =CarbonFootprint!I5 | F6: =CarbonFootprint!J5
A7: Gasolio per autotrazione | C7: 11811.97 | D7: 6763.24 | E7: =CarbonFootprint!I4 | F7: =CarbonFootprint!J4
A8: GPL per autotrazione
A9: Metano per autotrazione
A10: Metano per alimentazione caldaie/macchinari | C10: 182395 | D10: 189291 | E10: =CarbonFootprint!I2 | F10: =CarbonFootprint!J2
A11: GPL per alimentazione caldaie/macchinari
A12: Gasolio per alimentazione caldaie/macchinari
A13: *Aggiungere righe nella tabella se necessario
A14: Totale Energia rinnovabile | C14: =C4+C5 | D14: =D4+D5 | F14: =F4+F5
A15: Totale Energia non rinnovabile
A16: Totale rinnovabile e non rinnovabile
A18: A cura di Diligèa
A19: Emissioni GHG Scope 1
A20: Emissioni GHG Scope 2 (location-based)
A21: Emissioni GHG Scope 3 (location-based)
A22: GHG intensity | D22: =(D19+D20)/'B1'!B14 | F22: =(F19+F20)/'B1'!C14
A26: B3 - Energia e emissioni di gas a effetto serra | C26: 2024 | D26: Stat 2024 | E26: Totale 2024 | F26: 2025 | G26: Stat 2025 | H26: Totale 2025 | I26: Delta % 2025-2024
A27: Elettricità acquistata | C27: =C3 | D27: =D3 | E27: =SUM(D27+C27) | F27: =E3 | G27: =F3 | H27: =SUM(G27+F27) | I27: =H27/E27-1
A28: Elettricità autoprodotta da fonti rinnovabili | C28: =C5 | D28: =D5 | E28: =SUM(D28+C28) | F28: =E5 | G28: =F5 | H28: =SUM(G28+F28) | I28: =H28/E28-1
A29: Gas Naturale | C29: =C10 | D29: =D10 | E29: =SUM(D29+C29) | F29: =E10 | G29: =F10 | H29: =SUM(G29+F29) | I29: =H29/E29-1
A30: Gasolio | C30: =C7 | D30: =D7 | E30: =SUM(D30+C30) | F30: =E7 | G30: =F7 | H30: =SUM(G30+F30) | I30: =H30/E30-1
A31: Benzina | C31: =C6 | D31: =D6 | E31: =SUM(D31+C31) | F31: =E6 | G31: =F6 | H31: =SUM(G31+F31) | I31: =H31/E31-1

Sheet B3
A1: B3 - Energia e emissioni di gas a effetto serra
A2: B3 - Energia e emissioni di gas a effetto serra
A3: Energia elettrica acquistata senza GdO
A4: Energia elettrica acquistata con GdO
A5: Energia elettrica autoprodotta da fonti rinnovabili
A6: Benzina per autotrazione
A7: Gasolio per autotrazione
A8: GPL per autotrazione
A9: Metano per autotrazione
A10: Metano per alimentazione caldaie/macchinari
A11: GPL per alimentazione caldaie/macchinari
A12: Gasolio per alimentazione caldaie/macchinari
... A21: GHG intensity

Sheet B4
A1: Nota - compilare la tabella indicando le quantità corrispondenti a ciascuna sostanza inquinante che l'Organizzazione emette nell'aria, nell'acqua e nel suolo durante le proprie attività se: 1. l'Organizzazione è già tenuta per legge a comunicarle alle autorità competenti 2. l'Organizzazione le comunica volontariamente in base a un sistema di gestione ambientale
A3: B4 - Inquinamento di acqua, aria e suolo
A4: Inquinante | C4: Emissioni [kg] 2024 | D4: Emissioni [kg] 2025
A8: *Aggiungere linee se servono

Sheet B5
A1: B5 - Biodiversità
A2: B5 - Biodiversità
A3: Indirizzo
A4: Codice postale
A5: Città
A6: Paese
A7: Coordinate (geolocalizzazione)
A8: Area (ha)*
A9: Area protetta (biodiversity sensitive area)*
A10: Note
A11: *A cura di Diligèa
A13: Sede #1
... A19: Considerare non solo gli impatti locali ma anche quelli diretti e indiretti (es. tramite estrazione materie prime, catena di fornitura, produzione, trasporti e logistica, marketing e comunicazioni)

Sheet B7_M
A1: Nota - Se l'impresa opera in un settore che utilizza flussi di materiali significativi (ad esempio produzione, edilizia, imballaggio o altri), deve comunicare il flusso dei materiali rilevanti utilizzati. I dati relativi ai materiali possono essere omessi se trascurabili (es. consumabili uffici)
A3: B7 - Utilizzo delle risorse, economia circolare e gestione dei rifiuti
A4: Materiali significativi utilizzati (materie prime, materiali ausiliari, semilavorati) | C4: q.tà 2024 | D4: STAT q.tà 2024 | E4: STAT q.tà 20242 | F4: q.tà 2025 | G4: STAT q.tà 2025 | H4: Materiale riutilizzato/riciclato?
A5: CONSUMO ACQUA | C5: 1880 | F5: =CarbonFootprint!I7 | G5: =CarbonFootprint!J7
A6: Olio lubrificante | C6: 31524 | D6: 18673.3 | F6: =CarbonFootprint!I8 | G6: =CarbonFootprint!J8
A7: Acciaio inox | C7: 95221 | D7: 85223 | F7: =CarbonFootprint!I9 | G7: =CarbonFootprint!J9
A8: Acciaio | C8: 15752937 | D8: 9068602 | F8: =CarbonFootprint!I10 | G8: =CarbonFootprint!J10
A9: Alluminio | C9: 370234 | D9: 18974 | F9: =CarbonFootprint!I11 | G9: =CarbonFootprint!J11
A10: Azoto | C10: 46788 | F10: =CarbonFootprint!I12 | G10: =CarbonFootprint!J12
A11: CO2 | C11: 23840 | F11: =CarbonFootprint!I13 | G11: =CarbonFootprint!J13
A12: CO2 kg | D12: 8017 | F12: =CarbonFootprint!I14 | G12: =CarbonFootprint!J14
A13: Argon liquido kg | C13: 55486.46 | D13: 26487 | F13: =CarbonFootprint!I15 | G13: =CarbonFootprint!J15
A14: Ossigeno | C14: 2461 | D14: 2882 | F14: =CarbonFootprint!I16 | G14: =CarbonFootprint!J16
A15: Gas saldatura m3 | C15: 2765 | D15: 47 | F15: =CarbonFootprint!I17 | G15: =CarbonFootprint!J17
A16: Gas saldatura kg | D16: 1899 | F16: =CarbonFootprint!I18 | G16: =CarbonFootprint!J18
A17: Filo saldatura | C17: 105000 | D17: 12250 | F17: =CarbonFootprint!I19 | G17: =CarbonFootprint!J19
A18: Verniciatura | C18: 271421.51 | F18: =CarbonFootprint!I20 | G18: =CarbonFootprint!J20
A19: Verniciatura per kg | D19: 25100 | F19: =CarbonFootprint!I21 | G19: =CarbonFootprint!J21
A26: B7 - Altre informazioni: Utilizzo delle risorse, economia circolare e gestione dei rifiuti
A27: Comunicare se sono applicati i principi dell'economia circolare e, se sì, in che modo
A39: B7 - Utilizzo delle risorse, economia circolare e gestione dei rifiuti
A40: Materiali significativi utilizzati (materie prime, materiali ausiliari, semilavorati) | C40: q.tà 2024 | D40: STAT q.tà 2024 | E40: TOTALE 2024 | F40: q.tà 2025 | G40: STAT q.tà 2025 | H40: TOTALE 2025 | I40: Delta % 2025 - 2024
A41: CONSUMO ACQUA | C41: 1880 | E41: =D41+C41 | F41: 1970 | G41: 533 | H41: =G41+F41 | I41: =H41/E41-1
A42: Acciaio | C42: =C8 | D42: =D8 | E42: =D42+C42 | F42: =F8 | G42: =G8 | H42: =G42+F42 | I42: =H42/E42-1
A43: Acciaio inox | C43: =C7 | D43: =D7 | E43: =D43+C43 | F43: =F7 | G43: =G7 | H43: =G43+F43 | I43: =H43/E43-1
A44: Alluminio | C44: =C9 | D44: =D9 | E44: =D44+C44 | F44: =F9 | G44: =G9 | H44: =G44+F44 | I44: =H44/E44-1
A45: Olio lubrificante | C45: =C6 | D45: =D6 | E45: =D45+C45 | F45: =F6 | G45: =G6 | H45: =G45+F45 | I45: =H45/E45-1
A46: Azoto | C46: =C10 | E46: =D46+C46 | F46: 28666 | G46: 0 | H46: =G46+F46 | I46: =H46/E46-1
A47: CO2 | C47: 23840 | D47: 4055 | E47: =D47+C47 | F47: 42135 | G47: 1502.2762 | H47: =G47+F47 | I47: =H47/E47-1
A48: Argon liquido | C48: 55486.46 | D48: 26487 | E48: =D48+C48 | F48: 46275 | G48: 13163 | H48: =G48+F48 | I48: =H48/E48-1
A49: Ossigeno | C49: 2461 | D49: 2882 | E49: =D49+C49 | F49: 180 | G49: 43.6 | H49: =G49+F49 | I49: =H49/E49-1
A50: Gas saldatura | C50: 2765 | D50: =47+1042 | E50: =D50+C50 | F50: 1800 | G50: 8.75 | H50: =G50+F50 | I50: =H50/E50-1
A51: Filo saldatura | C51: 105000 | D51: 12250 | E51: =D51+C51 | F51: 69350 | G51: 11950 | H51: =G51+F51 | I51: =H51/E51-1
A52: Verniciatura | C52: 7070 | D52: 25100 | E52: =D52+C52 | F52: 7770.7 | G52: 24900 | H52: =G52+F52 | I52: =H52/E52-1
A55: B7 - Utilizzo delle risorse, economia circolare e gestione dei rifiuti
A56: Materiali significativi utilizzati (materie prime, materiali ausiliari, semilavorati) | C56: q.tà 2024 | D56: STAT q.tà 2024 | E56: TOTALE 2024 | F56: q.tà 2025 | G56: STAT q.tà 2025 | H56: TOTALE 2025 | I56: Delta % 2025 - 2024
A57: CONSUMO ACQUA | C57: =C41 | D57: =D41 | E57: =D57+C57 | F57: =F41 | G57: =G41 | H57: =G57+F57 | I57: =H57/E57-1
A58: Acciaio | C58: =C42/1000 | D58: =D42/1000 | E58: =D58+C58 | F58: =F42/1000 | G58: =G42/1000 | H58: =G58+F58 | I58: =H58/E58-1
A59: Acciaio inox | C59: =C43/1000 | D59: =D43/1000 | E59: =D59+C59 | F59: =F43/1000 | G59: =G43/1000 | H59: =G59+F59 | I59: =H59/E59-1
A60: Alluminio | C60: =C44/1000 | D60: =D44/1000 | E60: =D60+C60 | F60: =F44/1000 | G60: =G44/1000 | H60: =G60+F60 | I60: =H60/E60-1
...

Sheet B6
A1: B6 - Acqua
A2: Prelievo e consumo di acqua
A3: Prelievo da acquedotto
A4: Prelievo da pozzo
A5: Prelievo acque superficiali (es. laghi, fiumi)
A6: Prelievo di acqua da altre fonti (specificare)
A7: Totale prelievo idrico
A8: La zona di prelievo è soggetta a stress idrico?
A9: Se sì, specificare la quantità di acqua prelevata in siti soggetti ad alto stress idrico
A10: Quantità di acqua scaricata
A11: Consumo di acqua

Sheet B7_R
A1: Nota - i dati relativi ai rifiuti possono essere omessi se l'Organizzazione produce solo rifiuti urbani I VSME richiedono solo i totali in fondo, compilare la tabella con il dettaglio dei codici EER solo se è comodo per il calcolo o se interessa inserire un maggiore dettaglio in modo da tracciare eventuali variazioni da un anno all'altro
A3: B7 - Utilizzo delle risorse, economia circolare e gestione dei rifiuti
A4: Rifiuti (con codice EER) | B4: UdM | C4: Pericolosità | D4: Qtà 2024 | E4: Qtà STAT 2024 | F4: Trattamento 2024 | G4: Qtà 2025 | H4: Qtà STAT 2025 | I4: Trattamento 2025
A5: apparecchiature fuori uso 160214, diverse da quelle di cui alle voci da 160209 a 160213 | B5: kg | C5: Non pericoloso | D5: 231 | E5: 625 | F5: Riciclo/riutilizzo | G5: =CarbonFootprint!I22 | H5: =CarbonFootprint!J22 | I5: Riciclo/riutilizzo
A6: ferro e acciaio 170405 | B6: kg | C6: Non pericoloso | D6: 100 | E6: 139200 | F6: Riciclo/riutilizzo | G6: =CarbonFootprint!I23 | H6: =CarbonFootprint!J23 | I6: Riciclo/riutilizzo
A7: imballaggi in legno 150103 | B7: kg | C7: Non pericoloso | D7: 39140 | E7: 0 | F7: Riciclo/riutilizzo | G7: =CarbonFootprint!I24 | H7: =CarbonFootprint!J24 | I7: Riciclo/riutilizzo
A8: imballaggi in materiali misti 150106 | B8: kg | C8: Non pericoloso | D8: 49740 | E8: 82090 | F8: Riciclo/riutilizzo | G8: =CarbonFootprint!I25 | H8: =CarbonFootprint!J25 | I8: Riciclo/riutilizzo
A9: limatura e trucioli di materiali ferrosi 120101 | B9: kg | C9: Non pericoloso | D9: 49370 | F9: Riciclo/riutilizzo | G9: =CarbonFootprint!I26 | H9: =CarbonFootprint!J26 | I9: Riciclo/riutilizzo
A10: polveri e particolato di materiali ferrosi 120102 | B10: kg | C10: Non pericoloso | D10: 5733217 | E10: 2726070 | F10: Riciclo/riutilizzo | G10: =CarbonFootprint!I27 | H10: =CarbonFootprint!J27 | I10: Riciclo/riutilizzo
A11: polveri e particolato di materiali non ferrosi 120104 | B11: kg | C11: Non pericoloso | D11: 134870 | E11: 42760 | F11: Riciclo/riutilizzo | G11: =CarbonFootprint!I28 | H11: =CarbonFootprint!J28 | I11: Riciclo/riutilizzo
A12: rifiuti liquidi acquosi 161002, diversi da quelli di cui alla voce 16 10 01 | B12: kg | C12: Non pericoloso | D12: 26950 | F12: Smaltimento | G12: =CarbonFootprint!I29 | H12: =CarbonFootprint!J29 | I12: Smaltimento
A13: toner per stampa esauriti 080318, diversi da quelli di cui alla voce 080317 | B13: kg | C13: Non pericoloso | D13: 19 | F13: Riciclo/riutilizzo | G13: =CarbonFootprint!I30 | H13: =CarbonFootprint!J30 | I13: Riciclo/riutilizzo
A14: oli minerali per circuiti idraulici, non clorurati 130110 | B14: kg | C14: Pericoloso | D14: 3260 | F14: Smaltimento | G14: =CarbonFootprint!I31 | H14: =CarbonFootprint!J31 | I14: Smaltimento
A15: oli minerali per motori, ingranaggi e lubrificazione, non clorurati 130205 | B15: kg | C15: Pericoloso | D15: 4940 | F15: Smaltimento | G15: =CarbonFootprint!I32 | H15: =CarbonFootprint!J32 | I15: Smaltimento
A16: oli e altre emulsioni 130802 | B16: kg | C16: Pericoloso | D16: 13630 | F16: Smaltimento | G16: =CarbonFootprint!I33 | H16: =CarbonFootprint!J33 | I16: Smaltimento
A17: assorbenti, materiali filtranti (inclusi filtri dell'olio non specificati altrimenti), stracci e indumenti protettivi, contaminati da sostanze pericolose 150202 | B17: kg | C17: Pericoloso | D17: 2815 | F17: Smaltimento | G17: =CarbonFootprint!I34 | H17: =CarbonFootprint!J34 | I17: Smaltimento
A18: apparecchiature fuori uso, contenenti componenti pericolosi (3) 160213, diversi da quelli di cui alle voci da 160209 a 160212 | B18: kg | C18: Pericoloso | D18: 34 | F18: Smaltimento | G18: =CarbonFootprint!I35 | H18: =CarbonFootprint!J35 | I18: Smaltimento
A19: 150110 - imballaggi contenenti residui di sostanze pericolose o contaminati da tali sostanze | B19: kg | C19: Pericoloso | E19: 2330 | F19: Smaltimento | G19: =CarbonFootprint!I36 | H19: =CarbonFootprint!J36 | I19: Smaltimento
A20: 200121 - Tubi fluorescenti ed altri rifiuti contenenti mercurio | B20: kg | C20: Pericoloso | E20: 815 | F20: Smaltimento | G20: =CarbonFootprint!I37 | H20: =CarbonFootprint!J37 | I20: Smaltimento
A21: 120109 - Emulsioni e soluzioni per macchinari, non contenenti alogeni | B21: kg | C21: Pericoloso | G21: =CarbonFootprint!I38 | H21: 17200 | I21: Smaltimento
A22: 150110 - imballaggi contenenti residui di sostanze pericolose o contaminati da tali sostanze | B22: kg | C22: Pericoloso | G22: =CarbonFootprint!I39 | H22: 100 | I22: Smaltimento
A23: 200121 - Tubi fluorescenti ed altri rifiuti contenenti mercurio | B23: kg | C23: Pericoloso | G23: =CarbonFootprint!I40 | H23: 15 | I23: Riciclo/riutilizzo
A24: 130208 Altri oli per motori, ingranaggi e lubrificazione | B24: kg | C24: Pericoloso | G24: =CarbonFootprint!I41 | H24: 300 | I24: Riciclo/riutilizzo
A25: Imballaggi in plastica non pericolosi 150102 | B25: kg | C25: Non pericoloso | G25: =CarbonFootprint!I42 | H25: 20 | I25: Riciclo/riutilizzo
A26: Miscugli o scorie di cemento, mattoni, mattonelle e ceramiche, diverse da quelle di cui alla voce 17 01 06 170107 | B26: kg | C26: Non pericoloso | G26: =CarbonFootprint!I40 | H26: 13500 | I26: Riciclo/riutilizzo
A27: Rifiuti misti dell'attività di costruzione e demolizione, diversi da quelli di cui alle voci 17 09 01, 17 09 02 e 17 09 03 170904 | B27: kg | C27: Non pericoloso | G27: =CarbonFootprint!I39 | H27: 43710 | I27: Riciclo/riutilizzo
A28: Rifiuti urbani non differenziati 200301 | B28: kg | C28: Non pericoloso | G28: =CarbonFootprint!I41 | H28: 7317 | I28: Smaltimento
A29: Rifiuti ingombranti 200307 | B29: kg | C29: Non pericoloso | G29: =CarbonFootprint!I42 | H29: 14844 | I29: Riciclo/riutilizzo
A30: Componenti rimossi da apparecchiature fuori uso, diversi da quelli di cui alla voce 16 02 15 150216 | B30: kg | C30: Non pericoloso | G30: =CarbonFootprint!I38 | H30: 5120 | I30: Riciclo/riutilizzo
A31: Rifiuti organici, contenenti sostanze pericolose 160305 | B31: kg | C31: Pericoloso | H31: 1260 | I31: Smaltimento
A34: Quantità rifiuti pericolosi | D34: =SUMIF($C$5:$C$32,"Pericoloso",D$5:D$32) | E34: =SUMIF($C$5:$C$32,"Pericoloso",E$5:E$32) | G34: =SUMIF($C$5:$C$32,"Pericoloso",G$5:G$32) | H34: =SUMIF($C$5:$C$32,"Pericoloso",H$5:H$32)
A35: Quantità rifiuti non pericolosi | D35: =SUMIF($C$5:$C$32,"Non pericoloso",D$5:D$32) | E35: =SUMIF($C$5:$C$32,"Non pericoloso",E$5:E$32) | G35: =SUMIF($C$5:$C$32,"Non pericoloso",G$5:G$32) | H35: =SUMIF($C$5:$C$32,"Non pericoloso",H$5:H$32)
A36: Totale rifiuti | D36: =SUM(D34:D35) | E36: =SUM(E34:E35) | G36: =SUM(G34:G35) | H36: =SUM(H34:H35)
A37: Quantità rifiuti destinati a riciclo o riutilizzo | D37: =SUMIF(F$5:F$32,Elenchi!$B$3,D$5:D$32) | E37: =SUMIF(F$5:F$32,Elenchi!$B$3,E$5:E$32) | G37: =SUMIF(I$5:I$32,"Riciclo/riutilizzo",G$5:G$32) | H37: =SUMIF(I$5:I$32,Elenchi!$B$3,H$5:H$32)
A38: Quantità rifiuti destinati a smaltimento | D38: =SUMIF(F$5:F$32,"Smaltimento",D$5:D$32) | E38: =SUMIF(F$5:F$32,"Smaltimento",E$5:E$32) | G38: =SUMIF(I$5:I$32,"Smaltimento",G$5:G$32) | H38: =SUMIF(I$5:I$32,"Smaltimento",H$5:H$32)
A39: Totale rifiuti | D39: =SUM(D37:D38) | E39: =SUM(E37:E38) | G39: =SUM(G37:G38) | H39: =SUM(H37:H38)
A41: Il totale dei rifiuti per pericolosità e per trattamento deve coincidere
B48: 2024 | C48: Stat 2024 | D48: Totale 2024 | E48: 2025 | F48: Stat 2025 | G48: Totale 2025 | H48: Delta % 2025-2024
A49: =A34 | B49: =D34 | C49: =E34 | D49: =C49+B49 | E49: =G34 | F49: =H34 | G49: =F49+E49 | H49: =G49/D49-1
A50: =A35 | B50: =D35 | C50: =E35 | D50: =C50+B50 | E50: =G35 | F50: =H35 | G50: =F50+E50 | H50: =G50/D50-1
...

Sheet B8
A1: B8 - Forza lavoro: Caratteristiche generali
A3: Considerare i dati al 31/12 per la compilazione di queste tabelle
A4: Inserire i dati come headcount
A6: B8.1 - Numero dipendenti per tipologia contrattuale
A7: Tempo indeterminato
A8: Tempo determinato
A9: Totale dipendenti
A11: B8.2 - Numero lavoratori per genere
A12: Uomo
A13: Donna
A14: Altro
A15: Non segnalato
... A29: Totale dipendenti

Sheet B9-C6-C7
A1: B9 - Forza lavoro: Salute e sicurezza
A3: B9 - Infortuni sul lavoro
A4: Numero totale infortuni sul lavoro
A5: di cui con gravi conseguenze
A6: N.decessi da infortuni sul lavoro
A7: N.decessi da malattia professionale
A8: N. casi di malattia professionale registrabili
A9: TOT. ore ordinarie lavorate
A10: TOT. ore straordinarie lavorate
A11: TOT. ore lavorate
A12: TOT. ore perse per infortunio
A13: % ore perse sul totale
... A40: Se sì, specificare

Sheet B8-C5
A1: B8 - Forza lavoro: Caratteristiche generali
A3: Considerare i dati al 31/12 per la compilazione di queste tabelle
A4: Inserire i dati come headcount
A6: B8.1 - Numero dipendenti per tipologia contrattuale
A7: Tempo indeterminato
A8: Tempo determinato
A9: Apprendistato
A10: Totale dipendenti
A13: B8.2 - Numero lavoratori per genere
A14: Uomo
A15: Donna
A16: Altro
... A74: Totale

Sheet B9
A1: B9 - Forza lavoro: Salute e sicurezza
A2: B9 - Infortuni sul lavoro
A3: Numero totale infortuni sul lavoro
A4: di cui con gravi conseguenze
A5: N.decessi da infortuni sul lavoro
A6: N.decessi da malattia professionale
A7: N. casi di malattia professionale registrabili
A8: TOT. ore ordinarie lavorate
A9: TOT. ore straordinarie lavorate
A10: TOT. ore lavorate
A11: TOT. ore perse per infortunio
A12: % ore perse sul totale
A13: Tasso di infortunio (n.infortuni/totale ore lavorative)*200.000

Sheet B10
A1: B10 - Retribuzione, contrattazione collettiva e formazione
A3: B10.1 - Rapporto tra salario di ingresso e salario minimo
A4: Salario di ingresso
A5: Salario minimo
A6: Indice
A7: Percentage
A9: B10.2 - Pay Gap*
A10: Retribuzione lorda oraria media per i dipendenti di sesso maschile
A11: Retribuzione lorda oraria media per i dipendenti di sesso femminile
A12: Gender pay gap
A14: B10.3 - Contrattazione collettiva
A15: Numero di dipendenti coperti da contratti collettivi
... A27: Ore medie di formazione per dipendente

Sheet B11
A1: B11 - Condanne e sanzioni per corruzione e concussione
A3: Numero di condanne
A4: Importo totale sanzioni per violazione delle leggi anticorruzione e anticoncussione

Sheet B11-C8-C9
A1: B11 - Condanne e sanzioni per corruzione e concussione
B2: 2024 | C2: 2025
A3: Numero di condanne | B3: 0 | C3: 0
A4: Importo totale sanzioni per violazione delle leggi anticorruzione e anticoncussione | B4: 0 | C4: 0
A6: C8 - Ricavi in alcuni settori
B7: Ricavi [€] 2024 | C7: Ricavi [€] 2025
A8: Se l'impresa opera in uno o più dei seguenti settori, deve indicare i relativi ricavi: | B8: 0 | C8: 0
A9: a) armi controverse come mine antiuomo, munizioni a grappolo, armi chimiche e armi biologiche | B9: 0 | C9: 0
A10: b) coltivazione e produzione di tabacco | B10: 0 | C10: 0
A11: c) settore dei combustibili fossili (carbone, petrolio e gas)* | B11: 0 | C11: 0
A12: d) produzione di sostanze chimiche (ad es. pesticidi o altri prodotti agrochimici) | B12: 0 | C12: 0
A14: *l'impresa produce ricavi dall'esplorazione, dall'estrazione mineraria, dall'estrazione, dalla produzione, dalla trasformazione, dallo stoccaggio, dalla raffinazione o dalla distribuzione, compresi il trasporto, lo stoccaggio e il commercio, di combustibili fossili
A18: C9 - Diversità organo di governance
B19: 2024
A20: C9 - Diversità organo di governance | C20: Stat
A21: Numero membri di sesso femminile | B21: 2 | C21: 1
A22: Numero membri di sesso maschie | B22: 2 | C22: 3
A23: Totale | B23: =SUM(B21:B22) | C23: =SUM(C21:C22)
A24: Indice di diversità di genere | B24: =B21/B22 | C24: =C21/C22

Sheet Elenchi
A1: Sì
A2: No

Sheet C2
A1: C2 - Descrizione delle pratiche, politiche e iniziative future per la transizione verso un'economia più sostenibile
A3: Cambiamento climatico
A4: Inquinamento
A5: Acqua e risorse marine
A6: Biodiversità ed ecosistemi
A7: Economia circolare
A8: Forza lavoro propria
A9: Lavoratori nella catena del valore
A10: Comunità interessate
A11: Consumatori e utenti finali
A12: Condotta aziendale

Sheet C3
A1: C3 - Obiettivi di riduzione GHG
A2: Categoria GHG Protocol
A7: (per aziende che operano in settori ad alto impatto climatico)
A8: L'azienda ha adottato un piano di transizione per la mitigazione dei cambiamenti climatici?
A9: Sì: fornire informazioni a riguardo, compresa una spiegazione di come sta contribuendo alla riduzione delle emissioni di gas serra.
A10: No: indicare se e quando lo adotterà

Sheet C4
A1: C4 – Rischi climatici
A2: L'azienda ha individuato pericoli ed eventi di transizione legati al clima che creano rischi climatici rilevanti per l'impresa?
A3: Se sì: compilare la seguente tabella
A4: Descrizione pericolo/evento di transizione legato al clima

Sheet C5
A1: C5 - Forza lavoro: Ulteriori caratteristiche
A3: C5.1 - Diversità management
A4: Numero membri di sesso femminile
A5: Numero membri di sesso maschie
A6: Totale
A7: Indice di diversità di genere
A9: C5.2 - Forza lavoro esterna
A10: Lavoratori autonomi
A11: Lavoratori interinali
A12: Altro (specificare)
A13: Totale
A15: D5.3 - Numero dipendenti per inquadramento
... A39: Totale

Sheet C6
A1: C6 - Ulteriori informazioni sulla forza lavoro - Politiche e processi in materia di diritti umani
A2: C6 - Politiche e processi in materia di diritti umani
A3: L'impresa ha un codice di condotta o una politica sui diritti umani per il proprio personale?
A4: Se sì, riguarda:
A5: i. il lavoro minorile
A6: ii. Il lavoro forzato
A7: iii. la tratta di essere umani
A8: iv. la discriminazione
A9: v. la prevenzione degli infortuni
A10: vi. Altro (Se sì, specificare)
A12: L'impresa dispone di un meccanismo di gestione dei reclami per la propria forza lavoro?

Sheet C7
A1: C7 - Gravi incidenti negativi in materia di diritti umani
A2: C7 - Gravi incidenti negativi in materia di diritti umani
A3: L'impresa ha confermato episodi di incidenti nella propria forza lavoro relativi a:
A4: i. il lavoro minorile
A5: ii. Il lavoro forzato
A6: iii. la tratta di essere umani
A7: iv. la discriminazione
A8: v. Altro (Se sì, specificare)
A9: Se sì, specificare azioni intraprese
A11: L'impresa è a conoscenza di incidenti confermati che coinvolgono i lavoratori della catena del valore, le comunità interessate, i consumatori e gli utenti finali?
A12: Se sì, specificare

Sheet C8
A1: C8 - Ricavi in alcuni settori
B2: Ricavi [€] 2023 | C2: Ricavi [€] 2024
A3: Se l'impresa opera in uno o più dei seguenti settori, deve indicare i relativi ricavi:
A4: a) armi controverse come mine antiuomo, munizioni a grappolo, armi chimiche e armi biologiche
A5: b) coltivazione e produzione di tabacco
A6: c) settore dei combustibili fossili (carbone, petrolio e gas)*
A7: d) produzione di sostanze chimiche (ad es. pesticidi o altri prodotti agrochimici)
A9: *l'impresa produce ricavi dall'esplorazione, dall'estrazione mineraria, dall'estrazione, dalla produzione, dalla trasformazione, dallo stoccaggio, dalla raffinazione o dalla distribuzione, compresi il trasporto, lo stoccaggio e il commercio, di combustibili fossili

Sheet C9
A1: C9 - Diversità organo di governance
A2: C9 - Diversità organo di governance
A3: Numero membri di sesso femminile
A4: Numero membri di sesso maschie
A5: Totale
A6: Indice di diversità di genere
